Workbook

Sheet Sample
A1: Line in Master | B1: Company Name | C1: Year | D1: Reporting Period | E1: Reporting Year | F1: Publication Year | G1: Press Release Date
A2: 10 | B2: AdvanSix Inc | C2: 2021 | D2: 2020 calendar year | E2: 2020 | F2: 2021 | G2: 44326
A3: 11 | B3: Aflac Inc | C3: 2020 | D3: 2018 | E3: 2018 | F3: 2020 | G3: 43894
A4: 12 | B4: Agilent Technologies Inc | C4: 2021 | D4: 11/1/2019 - 10/31/2020 | E4: 2020 | F4: 2021 | G4: 44399
A5: 14 | B5: AGNC Investment Corp | C5: 2021 | D5: 2020 calendar year | E5: 2020 | F5: 2021 | G5: 44270
A6: 15 | B6: AIG - American International Group Inc | C6: 2021 | D6: 2020 calendar year | E6: 2020 | F6: 2021 | G6: 44377
A7: 17 | B7: Akamai Technologies Inc | C7: 2021 | D7: 2020 calendar year | E7: 2020 | F7: 2021 | G7: 44221
A8: 21 | B8: Albemarle Corp | C8: 2020 | D8: 2019 calendar year | E8: 2019 | F8: 2020 | G8: 44063
A9: 27 | B9: Alliance Data Systems Corp | C9: 2020 | D9: 2020 calendar year | E9: 2020 | F9: 2020 | G9: 43991
A10: 28 | B10: Alliance Data Systems Corp | C10: 2019 | D10: 2019 calendar year | E10: 2019 | F10: 2019 | G10: 43643
A11: 29 | B11: Alliant Energy Corp | C11: 2020 | D11: 2020 | E11: 2020 | F11: 2020 | G11: 44397
A12: 30 | B12: Allison Transmission Holdings Inc | C12: 2021 | D12: 2020 | E12: 2020 | F12: 2021 | G12: 44305
A13: 35 | B13: Ameren Corp | C13: 2021 | D13: 2020 calendar year | E13: 2020 | F13: 2021 | G13: 44322
A14: 36 | B14: American Airlines Group Inc | C14: 2020 | D14: 2019 calendar year | E14: 2019 | F14: 2020 | G14: 44119
A15: 39 | B15: American Express Co | C15: 2020 | D15: 2019 calendar year | E15: 2019 | F15: 2020 | G15: 44104
A16: 40 | B16: American Homes 4 Rent | C16: 2021 | D16: 2020 calendar year | E16: 2020 | F16: 2021 | G16: 44314
A17: 42 | B17: American Tower Corp | C17: 2020 | D17: 2019 calendar year | E17: 2019 | F17: 2020 | G17: 44036
A18: 48 | B18: Amphenol Corp | C18: 2021 | D18: 2020 calendar year | E18: 2020 | F18: 2021 | G18: 44361
A19: 49 | B19: Amphenol Corp | C19: 2020 | D19: 2019 calendar year | E19: 2019 | F19: 2020 | G19: 43985
A20: 50 | B20: Amphenol Corp | C20: 2019 | D20: 2018 calendar year | E20: 2018 | F20: 2019 | G20: 43711
A21: 51 | B21: Amyris Inc | C21: 2021 | D21: 2020 calendar year | E21: 2020 | F21: 2021 | G21: 44390
A22: 52 | B22: Annaly Capital Management Inc | C22: 2021 | D22: 2020 calendar year | E22: 2020 | F22: 2021 | G22: 44385
A23: 53 | B23: Annaly Capital Management Inc | C23: 2020 | D23: 2019 calendar year | E23: 2019 | F23: 2020 | G23: 44112
A24: 55 | B24: Antero Midstream | C24: 2020 | D24: 2019 | E24: 2019 | F24: 2020 | G24: 44109
A25: 56 | B25: Antero Resources Corp | C25: 2020 | D25: 2019 | E25: 2019 | F25: 2020 | G25: 44109
A26: 58 | B26: Apache Corp | C26: 2020 | D26: 2019 calendar year | E26: 2019 | F26: 2020 | G26: 44104
A27: 69 | B27: Arconic Corp | C27: 2020 | D27: 2019 | E27: 2019 | F27: 2020 | G27: 43993
A28: 70 | B28: Arcosa, Inc | C28: 2021 | D28: 2020 | E28: 2020 | F28: 2021 | G28: 44305
A29: 71 | B29: Arena Pharmaceuticals Inc | C29: 2021 | D29: 2020 | E29: 2020 | F29: 2021 | G29: 44305
A30: 75 | B30: Ashland LLC | C30: 2021 | D30: 2019 | E30: 2019 | F30: 2021 | G30: 44104
A31: 78 | B31: Atkore International | C31: 2021 | D31: 10/1/2018-9/1/2020 | E31: 2020 | F31: 2021 | G31: 44221
A32: 82 | B32: AvalonBay Communities Inc | C32: 2021 | D32: 2020 calendar year | E32: 2020 | F32: 2021 | G32: 44390
A33: 89 | B33: Barnes Group Inc | C33: 2021 | D33: 2020 calendar year | E33: 2020 | F33: 2021 | G33: 44291
A34: 90 | B34: Baxter International Inc | C34: 2020 | D34: 2019 calendar year | E34: 2019 | F34: 2020 | G34: 44151
A35: 91 | B35: Becton Dickinson and Co | C35: 2021 | D35: 10/1/2019-9/30/2020 | E35: 2020 | F35: 2021 | G35: 44369
A36: 94 | B36: Berry Plastics Group Inc | C36: 2021 | D36: 2020 | E36: 2020 | F36: 2021 | G36: 44259
A37: 98 | B37: Blackbaud, Inc. | C37: 2021 | D37: 2020 calendar year | E37: 2020 | F37: 2021 | G37: 44305
A38: 102 | B38: Bloom Energy Corp | C38: 2021 | D38: 2020 | E38: 2020 | F38: 2021 | G38: 44301
A39: 119 | B39: Bunge Ltd | C39: 2021 | D39: 2020 calendar year | E39: 2020 | F39: 2021 | G39: 44342
A40: 120 | B40: Burlington Stores Inc | C40: 2020 | D40: 2020 fiscal year (1/30/202020-1/30/2021) | E40: 2021 | F40: 2020 | G40: 44431
...

Sheet Compustat Links
A1: SASB Sample Name | B1: cusip | C1: Latest Annual datadate | D1: gvkey | E1: conm | F1: tic | G1: cik | H1: Name Match | I1: Checked? (1 if the SASB name does match with Compustat name) | J1: Note
A2: AdvanSix Inc | B2: 00773T101 | C2: 46022 | D2: 028070 | E2: ADVANSIX INC | F2: ASIX | G2: 1673985 | H2: =IF(E2=A2,1,"Check") -> 1 | I2: 1
A3: Aflac Inc | B3: 1055102 | C3: 46022 | D3: 001449 | E3: AFLAC INC | F3: AFL | G3: 4977 | H3: =IF(E3=A3,1,"Check") -> 1 | I3: 1
A4: Agilent Technologies Inc | B4: 00846U101 | C4: 45961 | D4: 126554 | E4: AGILENT TECHNOLOGIES INC | F4: A | G4: 1090872 | H4: =IF(E4=A4,1,"Check") -> 1 | I4: 1
A5: AGNC Investment Corp | B5: 00123Q104 | C5: 46022 | D5: 179889 | E5: AGNC INVESTMENT CORP | F5: AGNC | G5: 1423689 | H5: =IF(E5=A5,1,"Check") -> 1 | I5: 1
A6: AIG - American International Group Inc | B6: 26874784 | C6: 46022 | D6: 001487 | E6: AMERICAN INTERNATIONAL GROUP | F6: AIG | G6: 5272 | H6: =IF(E6=A6,1,"Check") -> Check | I6: 1
A7: Akamai Technologies Inc | B7: 00971T101 | C7: 46022 | D7: 125595 | E7: AKAMAI TECHNOLOGIES INC | F7: AKAM | G7: 1086222 | H7: =IF(E7=A7,1,"Check") -> 1 | I7: 1
A8: Albemarle Corp | B8: 12653101 | C8: 46022 | D8: 029751 | E8: ALBEMARLE CORP | F8: ALB | G8: 915913 | H8: =IF(E8=A8,1,"Check") -> 1 | I8: 1
A9: Alliance Data Systems Corp | B9: 18581108 | C9: 46022 | D9: 143974 | E9: BREAD FINANCIAL HOLDINGS INC | F9: BFH | G9: 1101215 | H9: =IF(E9=A9,1,"Check") -> Check | I9: Name change Alliance Data Systems Corporation -> Bread Financial in 2022
A10: Alliant Energy Corp | B10: 18802108 | C10: 46022 | D10: 011554 | E10: ALLIANT ENERGY CORP | F10: LNT | G10: 352541 | H10: =IF(E10=A10,1,"Check") -> 1 | I10: 1
A11: Allison Transmission Holdings Inc | B11: 01973R101 | C11: 46022 | D11: 177966 | E11: ALLISON TRANSMISSION HLDGS | F11: ALSN | G11: 1411207 | H11: =IF(E11=A11,1,"Check") -> Check | I11: 1
A12: Ameren Corp | B12: 23608102 | C12: 46022 | D12: 010860 | E12: AMEREN CORP | F12: AEE | G12: 1002910 | H12: =IF(E12=A12,1,"Check") -> 1 | I12: 1
A13: American Airlines Group Inc | B13: 02376R102 | C13: 46022 | D13: 001045 | E13: AMERICAN AIRLINES GROUP INC | F13: AAL | G13: 6201 | H13: =IF(E13=A13,1,"Check") -> 1 | I13: 1
A14: American Express Co | B14: 25816109 | C14: 46022 | D14: 001447 | E14: AMERICAN EXPRESS CO | F14: AXP | G14: 4962 | H14: =IF(E14=A14,1,"Check") -> 1 | I14: 1
A15: American Homes 4 Rent | B15: 02665T306 | C15: 46022 | D15: 017639 | E15: AMERICAN HOMES 4 RENT | F15: AMH | G15: 1562401 | H15: =IF(E15=A15,1,"Check") -> 1 | I15: 1
A16: American Tower Corp | B16: 03027X100 | C16: 46022 | D16: 105365 | E16: AMERICAN TOWER CORP | F16: AMT | G16: 1053507 | H16: =IF(E16=A16,1,"Check") -> 1 | I16: 1
A17: Amphenol Corp | B17: 32095101 | C17: 46022 | D17: 014282 | E17: AMPHENOL CORP | F17: APH | G17: 820313 | H17: =IF(E17=A17,1,"Check") -> 1 | I17: 1
A18: Amyris Inc | B18: 03236M200 | C18: 44926 | D18: 184717 | E18: AMYRIS INC | F18: AMRSQ | G18: 1365916 | H18: =IF(E18=A18,1,"Check") -> 1 | I18: 1
A19: Annaly Capital Management Inc | B19: 35710839 | C19: 46022 | D19: 065556 | E19: ANNALY CAPITAL MANAGEMENT | F19: NLY | G19: 1043219 | H19: =IF(E19=A19,1,"Check") -> Check | I19: 1
A20: Antero Midstream | B20: 03676B102 | C20: 46022 | D20: 031109 | E20: ANTERO MIDSTREAM CORP | F20: AM | G20: 1623925 | H20: =IF(E20=A20,1,"Check") -> Check | I20: name change - Antero Midstream became Antero Midstream Partners LP in 2014 after IPO
A21: Antero Resources Corp | B21: 03674X106 | C21: 46022 | D21: 018465 | E21: ANTERO RESOURCES CORP | F21: AR | G21: 1433270 | H21: =IF(E21=A21,1,"Check") -> 1 | I21: 1
A22: Apache Corp | B22: 03743Q108 | C22: 46022 | D22: 001678 | E22: APA CORP | F22: APA | G22: 1841666 | H22: =IF(E22=A22,1,"Check") -> Check | I22: Apache Corporation is a direct, wholly-owned subsidiary of APA
A23: Arconic Corp | B23: 03966V107 | C23: 44926 | D23: 035978 | E23: ARCONIC CORP | F23: ARNC | G23: 1790982 | H23: =IF(E23=A23,1,"Check") -> 1 | I23: 1 | J23: The company starts to trade in 2020 April, the shares outstanding in March 2019 is replaced as 109,021,376 (disclosed in its 2020 10-K https://www.sec.gov/Archives/edgar/data/1790982/000179098220000022/arconic10k.htm). The stock price is replaced as 6.92, the closing price of the first day of trade (April 1, 2020)
A24: Arcosa, Inc | B24: 39653100 | C24: 46022 | D24: 328795 | E24: ARCOSA INC | F24: ACA | G24: 1739445 | H24: =IF(E24=A24,1,"Check") -> Check | I24: 1
A25: Arena Pharmaceuticals Inc | B25: 40047607 | C25: 44561 | D25: 138122 | E25: ARENA PHARMACEUTICALS INC | F25: ARNA | G25: 1080709 | H25: =IF(E25=A25,1,"Check") -> 1 | I25: 1
A26: Ashland LLC | B26: 44186104 | C26: 45930 | D26: 001794 | E26: ASHLAND INC | F26: ASH | G26: 1674862 | H26: =IF(E26=A26,1,"Check") -> Check | I26: 1
A27: Atkore International | B27: 47649108 | C27: 45930 | D27: 027014 | E27: ATKORE INTERNATIONAL GROUP INC | F27: ATKR | G27: 1666138 | H27: Check | I27: 1 | J27: Update
A28: AvalonBay Communities Inc | B28: 53484101 | C28: 46022 | D28: 029875 | E28: AVALONBAY COMMUNITIES INC | F28: AVB | G28: 915912 | H28: =IF(E28=A28,1,"Check") -> 1 | I28: 1
A29: Barnes Group Inc | B29: 67806109 | C29: 45291 | D29: 002049 | E29: BARNES GROUP INC | F29: B.2 | G29: 9984 | H29: =IF(E29=A29,1,"Check") -> 1 | I29: 1
A30: Baxter International Inc | B30: 71813109 | C30: 46022 | D30: 002086 | E30: BAXTER INTERNATIONAL INC | F30: BAX | G30: 10456 | H30: =IF(E30=A30,1,"Check") -> 1 | I30: 1
A31: Becton Dickinson and Co | B31: 75887109 | C31: 45930 | D31: 002111 | E31: BECTON DICKINSON & CO | F31: BDX | G31: 10795 | H31: =IF(E31=A31,1,"Check") -> Check | I31: 1
A32: Berry Plastics Group Inc | B32: 08579X101 | C32: 45657 | D32: 013431 | E32: BERRY CORP | F32: BRY | G32: 1705873 | H32: =IF(E32=A32,1,"Check") -> Check | I32: Name change - Berry Plastics Group, Inc. changed its name to Berry Global Group, Inc. in 2017
A33: Blackbaud, Inc. | B33: 09227Q100 | C33: 46022 | D33: 260893 | E33: BLACKBAUD INC | F33: BLKB | G33: 1280058 | H33: =IF(E33=A33,1,"Check") -> Check | I33: 1
A34: Bloom Energy Corp | B34: 93712107 | C34: 46022 | D34: 033668 | E34: BLOOM ENERGY CORP | F34: BE | G34: 1664703 | H34: =IF(E34=A34,1,"Check") -> 1 | I34: 1
A35: Bunge Ltd | B35: H11356104 | C35: 46022 | D35: 144435 | E35: BUNGE GLOBAL SA | F35: BG | G35: 1996862 | H35: =IF(E35=A35,1,"Check") -> Check | I35: Name change - Bunge Ltd changed to Bunge Global SA
A36: Burlington Stores Inc | B36: 122017106 | C36: 46053 | D36: 018675 | E36: BURLINGTON STORES INC | F36: BURL | G36: 1579298 | H36: =IF(E36=A36,1,"Check") -> 1 | I36: 1
A37: Cabot Corp | B37: 127055101 | C37: 45930 | D37: 002593 | E37: CABOT CORP | F37: CBT | G37: 16040 | H37: =IF(E37=A37,1,"Check") -> 1 | I37: 1
A38: Cabot Oil & Gas Corp | B38: 127097103 | C38: 46022 | D38: 020548 | E38: COTERRA ENERGY INC | F38: CTRA | G38: 858470 | H38: =IF(E38=A38,1,"Check") -> Check | I38: Name change - Cabot Oil & Gas changed to Coterra Energy
A39: Calavo Growers Inc | B39: 128246105 | C39: 45961 | D39: 147708 | E39: CALAVO GROWERS INC | F39: CVGW | G39: 1133470 | H39: =IF(E39=A39,1,"Check") -> 1 | I39: 1
A40: California Water Service Group | B40: 130788102 | C40: 46022 | D40: 002628 | E40: CALIFORNIA WATER SERVICE GP | F40: CWT | G40: 1035201 | H40: =IF(E40=A40,1,"Check") -> Check | I40: 1
...

Sheet Compustat Controls
A1: lineinmaster | B1: SASB Sample Name | C1: reporting year | D1: cusip | E1: latestannualdatadate | F1: gvkey | G1: conm | H1: tic | I1: cik | J1: datadate | K1: at | L1: ceq | M1: che | N1: lt | O1: gp | P1: ni | Q1: sale | R1: csho | S1: prcc_f | T1: lnat | U1: roa | V1: lev | W1: gpm | X1: cash | Y1: loss | Z1: btm | AA1: Note
A2: 10 | B2: AdvanSix Inc | C2: 2020 | D2: 00773T101 | E2: 46022 | F2: 28070 | G2: ADVANSIX INC | H2: ASIX | I2: 1673985 | J2: 2020-12-31 | K2: 1263.407 | L2: 444.12299 | M2: 10.606 | N2: 819.284 | O2: 190.98801 | P2: 46.077 | Q2: 1157.917 | R2: 28.033001 | S2: 19.99 | T2: 7.1415672 | U2: 0.036470432 | V2: 0.64847195 | W2: 0.16494101 | X2: 0.008394761 | Y2: 0 | Z2: 0.79253942
A3: 11 | B3: Aflac Inc | C3: 2018 | D3: 1055102 | E3: 46022 | F3: 1449 | G3: AFLAC INC | H3: AFL | I3: 4977 | J3: 2018-12-31 | K3: 140406 | L3: 23462 | M3: 5530 | N3: 116944 | O3: 4338 | P3: 2920 | Q3: 21768 | R3: 755.28601 | S3: 45.560001 | T3: 11.852294 | U3: 0.020796832 | V3: 0.83289886 | W3: 0.19928335 | X3: 0.039385781 | Y3: 0 | Z3: 0.68182021
A4: 12 | B4: Agilent Technologies Inc | C4: 2020 | D4: 00846U101 | E4: 45961 | F4: 126554 | G4: AGILENT TECHNOLOGIES INC | H4: A | I4: 1090872 | J4: 2020-10-31 | K4: 9627 | L4: 4873 | M4: 1441 | N4: 4754 | O4: 3068 | P4: 719 | Q4: 5339 | R4: 306.198 | S4: 102.09 | T4: 9.172327 | U4: 0.074685782 | V4: 0.49381948 | W4: 0.57463944 | X4: 0.14968318 | Y4: 0 | Z4: 0.15588735
A5: 14 | B5: AGNC Investment Corp | C5: 2020 | D5: 00123Q104 | E5: 46022 | F5: 179889 | G5: AGNC INVESTMENT CORP | H5: AGNC | I5: 1423689 | J5: 2020-12-31 | K5: 81817 | L5: 9590 | M5: 2324 | N5: 70738 | O5: 2871 | P5: -266 | Q5: 2964 | R5: 539.46899 | S5: 15.6 | T5: 11.312241 | U5: -0.0032511582 | V5: 0.86458802 | W5: 0.96862346 | X5: 0.028404854 | Y5: 1 | Z5: 1.1395346
A6: 15 | B6: AIG - American International Group Inc | C6: 2020 | D6: 26874784 | E6: 46022 | F6: 1487 | G6: AMERICAN INTERNATIONAL GROUP | H6: AIG | I6: 5272 | J6: 2020-12-31 | K6: 586481 | L6: 65877 | M6: 31987 | N6: 519282 | O6: 6985 | P6: -5944 | Q6: 43358 | R6: 861.55798 | S6: 37.860001 | T6: 13.281896 | U6: -0.010135026 | V6: 0.88541996 | W6: 0.16110061 | X6: 0.054540556 | Y6: 1 | Z6: 2.0196154
A7: 17 | B7: Akamai Technologies Inc | C7: 2020 | D7: 00971T101 | E7: 46022 | F7: 125595 | G7: AKAMAI TECHNOLOGIES INC | H7: AKAM | I7: 1086222 | J7: 2020-12-31 | K7: 7764.1299 | L7: 4251.2959 | M7: 1098.073 | N7: 3512.834 | O7: 2385.7749 | P7: 557.05402 | Q7: 3198.1489 | R7: 162.71001 | S7: 104.99 | T7: 8.9572697 | U7: 0.071747124 | V7: 0.45244399 | W7: 0.74598616 | X7: 0.14142898 | Y7: 0 | Z7: 0.24886233
A8: 21 | B8: Albemarle Corp | C8: 2019 | D8: 12653101 | E8: 46022 | F8: 29751 | G8: ALBEMARLE CORP | H8: ALB | I8: 915913 | J8: 2019-12-31 | K8: 9860.8633 | L8: 3932.25 | M8: 613.10999 | N8: 5767.2832 | O8: 1472.962 | P8: 533.22803 | Q8: 3589.427 | R8: 106.04 | S8: 73.040001 | T8: 9.1963291 | U8: 0.054075189 | V8: 0.58486593 | W8: 0.41036132 | X8: 0.062176097 | Y8: 0 | Z8: 0.50770408
A9: 27 | B9: Alliance Data Systems Corp | C9: 2020 | D9: 18581108 | E9: 46022 | F9: 143974 | G9: BREAD FINANCIAL HOLDINGS INC | H9: BFH | I9: 1101215 | J9: 2020-12-31 | K9: 22547.1 | L9: 1521.6 | M9: 4146.2002 | N9: 21025.5 | O9: 2491.6001 | P9: 213.7 | Q9: 4521.3999 | R9: 49.700001 | S9: 74.099998 | T9: 10.023362 | U9: 0.0094779376 | V9: 0.93251461 | W9: 0.55106831 | X9: 0.18389063 | Y9: 0 | Z9: 0.41316727
A10: 28 | B10: Alliance Data Systems Corp | C10: 2019 | D10: 18581108 | E10: 46022 | F10: 143974 | G10: BREAD FINANCIAL HOLDINGS INC | H10: BFH | I10: 1101215 | J10: 2019-12-31 | K10: 26494.801 | L10: 1588.3 | M10: 4550.8999 | N10: 24906.5 | O10: 2967.6001 | P10: 278 | Q10: 5581.2998 | R10: 47.599998 | S10: 112.2 | T10: 10.184704 | U10: 0.010492625 | V10: 0.94005233 | W10: 0.53170413 | X10: 0.17176577 | Y10: 0 | Z10: 0.29739439
A11: 29 | B11: Alliant Energy Corp | C11: 2020 | D11: 18802108 | E11: 46022 | F11: 11554 | G11: ALLIANT ENERGY CORP | H11: LNT | I11: 352541 | J11: 2020-12-31 | K11: 17710 | L11: 5688 | M11: 54 | N11: 11822 | O11: 1348 | P11: 624 | Q11: 3416 | R11: 249.868 | S11: 51.529999 | T11: 9.7818851 | U11: 0.035234332 | V11: 0.66753244 | W11: 0.39461359 | X11: 0.0030491247 | Y11: 0 | Z11: 0.44176248
A12: 30 | B12: Allison Transmission Holdings Inc | C12: 2020 | D12: 01973R101 | E12: 46022 | F12: 177966 | G12: ALLISON TRANSMISSION HLDGS | H12: ALSN | I12: 1411207 | J12: 2020-12-31 | K12: 4477 | L12: 756 | M12: 310 | N12: 3721 | O12: 1151 | P12: 299 | Q12: 2081 | R12: 112.033 | S12: 43.130001 | T12: 8.4067087 | U12: 0.066785797 | V12: 0.83113694 | W12: 0.55309945 | X12: 0.069242798 | Y12: 0 | Z12: 0.1564575
A13: 35 | B13: Ameren Corp | C13: 2020 | D13: 23608102 | E13: 46022 | F13: 10860 | G13: AMEREN CORP | H13: AEE | I13: 1002910 | J13: 2020-12-31 | K13: 32030 | L13: 8938 | M13: 156 | N13: 22950 | O13: 2375 | P13: 871 | Q13: 5794 | R13: 253.3 | S13: 78.059998 | T13: 10.374428 | U13: 0.027193256 | V13: 0.71651578 | W13: 0.4099068 | X13: 0.0048704338 | Y13: 0 | Z13: 0.45203975
... A26: 58 | B26: Apache Corp | C26: 2019 | D26: 03743Q108 | E26: 46022 | F26: 1678 | G26: APA CORP | H26: APA | I26: 1841666 | J26: 2019-12-31 | K26: 18107 | L26: 3255 | M26: 247 | N26: 13087 | O26: 1520 | P26: -3553 | Q26: 6280 | R26: 376.06299 | S26: 25.59 | T26: 9.8040543 | U26: -0.19622245 | V26: 0.72275913 | W26: 0.24203822 | X26: 0.013641133 | Y26: 1 | Z26: 0.33823621
A27: 69 | B27: Arconic Corp | C27: 2019 | D27: 03966V107 | E27: 44926 | F27: 35978 | G27: ARCONIC CORP | H27: ARNC | I27: 1790982 | J27: 2019-12-31 | K27: 4741 | L27: 2714 | M27: 72 | N27: 2013 | O27: 1007 | P27: 225 | Q27: 7277 | R27: 109.02 | S27: 6.9200001 | T27: 8.4640036 | U27: 0.047458343 | V27: 0.42459396 | W27: 0.1383812 | X27: 0.015186669 | Y27: 0 | Z27: 3.5974734 | AA27: The company starts to trade in 2020 April, the shares outstanding in March 2019 is replaced as 109,021,376 (disclosed in its 2020 10-K https://www.sec.gov/Archives/edgar/data/1790982/000179098220000022/arconic10k.htm). The stock price is replaced as 6.92, the closing price of the first day of trade (April 1, 2020)
A28: 70 | B28: Arcosa, Inc | C28: 2020 | D28: 39653100 | E28: 46022 | F28: 328795 | G28: ARCOSA INC | H28: ACA | I28: 1739445 | J28: 2020-12-31 | K28: 2646.7 | L28: 1892.2 | M28: 95.800003 | N28: 754.5 | O28: 506.79999 | P28: 106.6 | Q28: 1935.6 | R28: 48.200001 | S28: 54.93 | T28: 7.8810687 | U28: 0.040276572 | V28: 0.28507197 | W28: 0.26183096 | X28: 0.03619602 | Y28: 0 | Z28: 0.71467793
A29: 71 | B29: Arena Pharmaceuticals Inc | C29: 2020 | D29: 40047607 | E29: 44561 | F29: 138122 | G29: ARENA PHARMACEUTICALS INC | H29: ARNA | I29: 1080709 | J29: 2020-12-31 | K29: 1190.72 | L29: 1080.469 | M29: 1104.041 | N29: 110.251 | O29: -422.78101 | P29: -404.73401 | Q29: 0.31900001 | R29: 58.611 | S29: 76.830002 | T29: 7.0823135 | U29: -0.33990696 | V29: 0.092591882 | W29: -1325.3323 | X29: 0.92720461 | Y29: 1 | Z29: 0.23993982
A30: 75 | B30: Ashland LLC | C30: 2019 | D30: 44186104 | E30: 45930 | F30: 1794 | G30: ASHLAND INC | H30: ASH | I30: 1674862 | J30: 2019-09-30 | K30: 7251 | L30: 3571 | M30: 256 | N30: 3680 | O30: 980 | P30: 505 | Q30: 2493 | R30: 60 | S30: 77.050003 | T30: 8.888895 | U30: 0.069645569 | V30: 0.50751621 | W30: 0.39310068 | X30: 0.035305474 | Y30: 0 | Z30: 0.7724421
A31: 78 | B31: Atkore International | C31: 2020 | D31: 47649108 | E31: 45930 | F31: 27014 | G31: ATKORE INTERNATIONAL GROUP INC | H31: ATKR | I31: 1666138 | J31: 2020-09-30 | K31: 1558.525 | L31: 378.41 | M31: 284.47101 | N31: 1180.115 | O31: 533.52197 | P31: 152.302 | Q31: 1765.421 | R31: 47.407001 | S31: 22.73 | T31: 7.3514953 | U31: 0.097721882 | V31: 0.75719988 | W31: 0.30220664 | X31: 0.18252578 | Y31: 0 | Z31: 0.35117266
A32: 82 | B32: AvalonBay Communities Inc | C32: 2020 | D32: 53484101 | E32: 46022 | F32: 29875 | G32: AVALONBAY COMMUNITIES INC | H32: AVB | I32: 915912 | J32: 2020-12-31 | K32: 19199.145 | L32: 10751.583 | M32: 313.53201 | N32: 8444.293 | O32: 776.86499 | P32: 827.63 | Q32: 2307.2981 | R32: 139.52699 | S32: 160.42999 | T32: 9.8626213 | U32: 0.043107651 | V32: 0.43982652 | W32: 0.33669901 | X32: 0.01633052 | Y32: 0 | Z32: 0.48031771
A33: 89 | B33: Barnes Group Inc | C33: 2020 | D33: 67806109 | E33: 45291 | F33: 2049 | G33: BARNES GROUP INC | H33: B.2 | I33: 9984 | J33: 2020-12-31 | K33: 2676.2261 | L33: 1382.677 | M33: 84.088997 | N33: 1293.549 | O33: 490.80899 | P33: 63.375 | Q33: 1124.391 | R33: 50.640999 | S33: 50.689999 | T33: 7.8921628 | U33: 0.023680735 | V33: 0.48334816 | W33: 0.43651095 | X33: 0.031420738 | Y33: 0 | Z33: 0.53863704
A34: 90 | B34: Baxter International Inc | C34: 2019 | D34: 71813109 | E34: 46022 | F34: 2086 | G34: BAXTER INTERNATIONAL INC | H34: BAX | I34: 10456 | J34: 2019-12-31 | K34: 18193 | L34: 7882 | M34: 3335 | N34: 10281 | O34: 5705 | P34: 1001 | Q34: 11362 | R34: 506.155 | S34: 83.620003 | T34: 9.8087921 | U34: 0.055021163 | V34: 0.56510746 | W34: 0.50211233 | X34: 0.18331227 | Y34: 0 | Z34: 0.18622704
A35: 91 | B35: Becton Dickinson and Co | C35: 2020 | D35: 75887109 | E35: 45930 | F35: 2111 | G35: BECTON DICKINSON & CO | H35: BDX | I35: 10795 | J35: 2020-09-30 | K35: 54012 | L35: 23763 | M35: 2937 | N35: 30247 | O35: 9875 | P35: 874 | Q35: 17117 | R35: 290.017 | S35: 232.67999 | T35: 10.896961 | U35: 0.01618159 | V35: 0.56000519 | W35: 0.57691187 | X35: 0.054376803 | Y35: 0 | Z35: 0.35214278
A36: 94 | B36: Berry Plastics Group Inc | C36: 2020 | D36: 08579X101 | E36: 45657 | F36: 13431 | G36: BERRY CORP | H36: BRY | I36: 1705873 | J36: 2020-12-31 | K36: 1419.8101 | L36: 714.03601 | M36: 80.556999 | N36: 705.77399 | O36: -12.098 | P36: -262.89499 | Q36: 523.83301 | R36: 79.929001 | S36: 3.6800001 | T36: 7.2582784 | U36: -0.18516208 | V36: 0.49709043 | W36: -0.023095146 | X36: 0.05673787 | Y36: 1 | Z36: 2.4275484
A37: 98 | B37: Blackbaud, Inc. | C37: 2020 | D37: 09227Q100 | E37: 46022 | F37: 260893 | G37: BLACKBAUD INC | H37: BLKB | I37: 1280058 | J37: 2020-12-31 | K37: 2044.734 | L37: 426.14999 | M37: 644.96899 | N37: 1618.584 | O37: 579.27399 | P37: 7.717 | Q37: 913.21899 | R37: 48.849998 | S37: 57.560001 | T37: 7.623023 | U37: 0.0037740851 | V37: 0.79158658 | W37: 0.63432097 | X37: 0.3154293 | Y37: 0 | Z37: 0.1515574
A38: 102 | B38: Bloom Energy Corp | C38: 2020 | D38: 93712107 | E38: 46022 | F38: 33668 | G38: BLOOM ENERGY CORP | H38: BE | I38: 1664703 | J38: 2020-12-31 | K38: 1454.387 | L38: 78.823997 | M38: 299.41699 | N38: 1312.991 | O38: 218.07201 | P38: -157.55299 | Q38: 794.24701 | R38: 168.00301 | S38: 28.66 | T38: 7.2823396 | U38: -0.10832949 | V38: 0.90277964 | W38: 0.27456447 | X38: 0.20587161 | Y38: 1 | Z38: 0.016370624
A39: 119 | B39: Bunge Ltd | C39: 2020 | D39: H11356104 | E39: 46022 | F39: 144435 | G39: BUNGE GLOBAL SA | H39: BG | I39: 1996862 | J39: 2020-12-31 | K39: 23655 | L39: 5379 | M39: 1544 | N39: 17035 | O39: 3169 | P39: 1145 | Q39: 41355 | R39: 139.78999 | S39: 65.580002 | T39: 10.07133 | U39: 0.048404142 | V39: 0.72014374 | W39: 0.076629184 | X39: 0.065271616 | Y39: 0 | Z39: 0.58675128
... A47: 130 | B47: Cardinal Health Inc | C47: 2020 | D47: 14149Y108 | E47: 45838 | F47: 2751 | G47: CARDINAL HEALTH INC | H47: CAH | I47: 721371 | J47: 2020-06-30 | K47: 40766 | L47: 1789 | M47: 2771 | N47: 38974 | O47: 7268 | P47: -3696 | Q47: 152922 | R47: 293 | S47: 52.189999 | T47: 10.615603 | U47: -0.090663791 | V47: 0.95604181 | W47: 0.047527499 | X47: 0.067973308 | Y47: 1 | Z47: 0.1169918
A48: 131 | B48: Carrier Global Corp | C48: 2019 | D48: 14448C104 | E48: 46022 | F48: 36191 | G48: CARRIER GLOBAL CORP | H48: CARR | I48: 1783180 | J48: 2019-12-31 | K48: 22406 | L48: 14102 | M48: 957 | N48: 7971 | O48: 5790 | P48: 2116 | Q48: 18608 | R48: 866.15997 | S48: 16.92 | T48: 10.017084 | U48: 0.094438992 | V48: 0.35575292 | W48: 0.31115648 | X48: 0.042711772 | Y48: 0 | Z48: 0.96223742 | AA48: starts to trade on April 3 2020 -> The shares outstainding is replaced as 866,158,910 shares as if on the spin-off day (in 10-K https://www.sec.gov/ix?doc=/Archives/edgar/data/0001783180/000178318021000011/carr-20201231.htm), the stock price is replaced as 16.92, the closing price of the first date of trading (April 3, 2020)
A49: 132 | B49: Catalent Inc | C49: 2021 | D49: 148806102 | E49: 45473 | F49: 20228 | G49: CATALENT INC | H49: CTLT | I49: 1596783 | J49: 2021-06-30 | K49: 9112 | L49: 3915 | M49: 967 | N49: 4838 | O49: 1673 | P49: 585 | Q49: 3998 | R49: 170.549 | S49: 108.12 | T49: 9.1173477 | U49: 0.064201057 | V49: 0.53094822 | W49: 0.41845924 | X49: 0.10612379 | Y49: 0 | Z49: 0.21231298
A50: 133 | B50: Catalent Inc | C50: 2019 | D50: 148806102 | E50: 45473 | F50: 20228 | G50: CATALENT INC | H50: CTLT | I50: 1596783 | J50: 2019-06-30 | K50: 6184 | L50: 1681.6 | M50: 345.39999 | N50: 3895.8 | O50: 1033.7 | P50: 137.39999 | Q50: 2518 | R50: 145.73801 | S50: 54.209999 | T50: 8.7297201 | U50: 0.022218628 | V50: 0.62998062 | W50: 0.41052422 | X50: 0.055853814 | Y50: 0 | Z50: 0.21284844
A51: 134 | B51: Caterpillar Inc | C51: 2020 | D51: 149123101 | E51: 46022 | F51: 2817 | G51: CATERPILLAR INC | H51: CAT | I51: 18230 | J51: 2020-12-31 | K51: 78324 | L51: 15331 | M51: 9502 | N51: 62946 | O51: 14384 | P51: 2998 | Q51: 41748 | R51: 545.30402 | S51: 182.02 | T51: 11.268609 | U51: 0.0382769 | V51: 0.8036617 | W51: 0.34454346 | X51: 0.12131658 | Y51: 0 | Z51: 0.15445881
A52: 142 | B52: Century Communities Inc | C52: 2020 | D52: 156504300 | E52: 46022 | F52: 18004 | G52: CENTURY COMMUNITIES INC | H52: CCS | I52: 1576940 | J52: 2020-12-31 | K52: 2845.093 | L52: 1280.705 | M52: 421.23001 | N52: 1564.3879 | O52: 630.302 | P52: 206.157 | Q52: 3161.1919 | R52: 33.351002 | S52: 43.779999 | T52: 7.953351 | U52: 0.072460547 | V52: 0.54985476 | W52: 0.19938746 | X52: 0.14805491 | Y52: 0 | Z52: 0.87713099
A53: 146 | B53: CH Robinson Worldwide Inc | C53: 2020 | D53: 12541W209 | E53: 45657 | F53: 65609 | G53: C H ROBINSON WORLDWIDE INC | H53: CHRW | I53: 1043277 | J53: 2020-12-31 | K53: 5144.2578 | L53: 1879.933 | M53: 243.79601 | N53: 3264.325 | O53: 2513.9839 | P53: 506.42099 | Q53: 16207.106 | R53: 134.298 | S53: 93.870003 | T53: 8.5456362 | U53: 0.09844394 | V53: 0.63455701 | W53: 0.15511614 | X53: 0.047391873 | Y53: 0 | Z53: 0.14912346
A54: 147 | B54: Charah Solutions Inc | C54: 2020 | D54: 15957P303 | E54: 44926 | F54: 33596 | G54: CHARAH SOLUTIONS | H54: CHRA | I54: 1730346 | J54: 2020-12-31 | K54: 280.95999 | L54: 19.906 | M54: 29.211 | N54: 233.22099 | O54: 41.938 | P54: -55.862999 | Q54: 232.377 | R54: 30.077 | S54: 2.8699999 | T54: 5.6382122 | U54: -0.19882901 | V54: 0.83008611 | W54: 0.18047397 | X54: 0.10396854 | Y54: 1 | Z54: 0.23060441
A55: 149 | B55: Chart Industries Inc | C55: 2020 | D55: 16115Q308 | E55: 45657 | F55: 25964 | G55: CHART INDUSTRIES INC | H55: GTLS | I55: 892553 | J55: 2020-12-31 | K55: 2570.5 | L55: 1572.7 | M55: 126.1 | N55: 991.20001 | O55: 376.60001 | P55: 308.10001 | Q55: 1177.1 | R55: 35.424999 | S55: 117.79 | T55: 7.8518558 | U55: 0.11985995 | V55: 0.38560593 | W55: 0.31993884 | X55: 0.049056605 | Y55: 0 | Z55: 0.37690127
A56: 152 | B56: Chemours Co/The | C56: 2019 | D56: 163851108 | E56: 46022 | F56: 22741 | G56: CHEMOURS CO | H56: CC | I56: 1627223 | J56: 2019-12-31 | K56: 7258 | L56: 689 | M56: 943 | N56: 6563 | O56: 1524 | P56: -52 | Q56: 5526 | R56: 163.57401 | S56: 18.09 | T56: 8.8898592 | U56: -0.0071645081 | V56: 0.90424359 | W56: 0.27578717 | X56: 0.12992559 | Y56: 1 | Z56: 0.23284471
A57: 154 | B57: Cheniere Energy Partners LP | C57: 2020 | D57: 16411Q101 | E57: 43830 | F57: 176914 | G57: CHENIERE ENERGY PARTNERS LP | H57: CQP | I57: 1383650 | J57: 2020-12-31 | K57: 19145 | L57: 539 | M57: 1307 | N57: 18606 | O57: 2827 | P57: 1183 | Q57: 6167 | R57: 484 | S57: 35.25 | T57: 9.8597965 | U57: 0.061791591 | V57: 0.97184646 | W57: 0.45840764 | X57: 0.068268478 | Y57: 0 | Z57: 0.031592522
A58: 157 | B58: Chipotle Mexican Grill Inc | C58: 2020 | D58: 169656105 | E58: 46022 | F58: 165914 | G58: CHIPOTLE MEXICAN GRILL INC | H58: CMG | I58: 1058090 | J58: 2020-12-31 | K58: 5982.896 | L58: 2020.135 | M58: 951.60303 | N58: 3962.761 | O58: 1035.65 | P58: 355.76599 | Q58: 5984.6338 | R58: 28.000999 | S58: 1386.71 | T58: 8.69666 | U58: 0.059463844 | V58: 0.66234827 | W58: 0.17305152 | X58: 0.15905392 | Y58: 0 | Z58: 0.052026093
A59: 164 | B59: Citigroup Inc (Citi) | C59: 2020 | D59: 172967424 | E59: 46022 | F59: 3243 | G59: CITIGROUP INC | H59: C | I59: 831001 | J59: 2020-12-31 | K59: 2260090 | L59: 179962 | M59: 605047 | N59: 2059890 | O59: 25573 | P59: 11047 | Q59: 88839 | R59: 2082.0901 | S59: 61.66 | T59: 14.630916 | U59: 0.0048878584 | V59: 0.91141945 | W59: 0.2878578 | X59: 0.26770926 | Y59: 0 | Z59: 1.4017732
...

Sheet Metrics
A1: Industry | B1: Topics | C1: Code | D1: Quantitative | E1: Metrics | F1: MonetaryLoss
A2: ADVERTISING & MARKETING | B2: Data Privacy | C2: SV-AD-220a.1 | D2: 0 | E2: Discussion of policies and practices relating to behavioral advertising and consumer privacy
B3: Data Privacy | C3: SV-AD-220a.2 | D3: 1 | E3: Percentage of online advertising impressions that are targeted to custom audiences
B4: Data Privacy | C4: SV-AD-220a.3 | D4: 1 | E4: Total amount of monetary losses as a result of legal proceedings associated with consumer privacy | F4: 1
B5: Advertising Integrity | C5: SV-AD-270a.1 | D5: 1 | E5: Total amount of monetary losses as a result of legal proceedings associated with false, deceptive, or unfair advertising | F5: 1
B6: Advertising Integrity | C6: SV-AD-270a.2 | D6: 1 | E6: Percentage of campaigns reviewed for adherence with the Advertising Self- Regulatory Council (ASRC) procedures, percentage of those in compliance
B7: Advertising Integrity | C7: SV-AD-270a.3 | D7: 1 | E7: Percentage of campaigns that promote alcohol or tobacco products
B8: Workforce Diversity & Inclusion | C8: SV-AD-330a.1 | D8: 1 | E8: Percentage of gender and racial/ethnic group representation for (1) management, (2) professionals, and (3) all other employees
A9: AEROSPACE & DEFENSE | B9: Energy Management | C9: RT-AE-130a.1 | D9: 1 | E9: (1) Total energy consumed, (2) percentage grid electricity, (3) percentage renewable
B10: Hazardous Waste Management | C10: RT-AE-150a.1 | D10: 1 | E10: Amount of hazardous waste generated, percentage recycled
B11: Hazardous Waste Management | C11: RT-AE-150a.2 | D11: 1 | E11: Number and aggregate quantity of reportable spills, quantity recovered
B12: Data Security | C12: RT-AE-230a.1 | D12: 1 | E12: (1) Number of data breaches, (2) percentage involving confidential information
B13: Data Security | C13: RT-AE-230a.2 | D13: 0 | E13: Description of approach to identifying and addressing data security risks in (1) company operations and (2) products
B14: Product Safety | C14: RT-AE-250a.1 | D14: 1 | E14: Number of recalls issued, total units recalled
B15: Product Safety | C15: RT-AE-250a.2 | D15: 1 | E15: Number of counterfeit parts detected, percentage avoided
B16: Product Safety | C16: RT-AE-250a.3 | D16: 1 | E16: Number of Airworthiness Directives received, total units affected
B17: Product Safety | C17: RT-AE-250a.4 | D17: 1 | E17: Total amount of monetary losses as a result of legal proceedings associated with product safety | F17: 1
B18: Fuel Economy & Emissions in Use-phase | C18: RT-AE-410a.1 | D18: 1 | E18: Revenue from alternative energy-related products
B19: Fuel Economy & Emissions in Use-phase | C19: RT-AE-410a.2 | D19: 0 | E19: Description of approach and discussion of strategy to address fuel economy and greenhouse gas (GHG) emissions of products
B20: Materials Sourcing | C20: RT-AE-440a.1 | D20: 0 | E20: Description of the management of risks associated with the use of critical materials
B21: Business Ethics | C21: RT-AE-510a.1 | D21: 1 | E21: Total amount of monetary losses as a result of legal proceedings associated with incidents of corruption, bribery, and/or illicit international trade | F21: 1
B22: Business Ethics | C22: RT-AE-510a.2 | D22: 1 | E22: Revenue from countries ranked in the “E” or“F” Band of Transparency International’sGovernment Defence Anti-Corruption Index
B23: Business Ethics | C23: RT-AE-510a.3 | D23: 0 | E23: Discussion of processes to manage business ethics risks throughout the value chain
A24: AGRICULTURAL PRODUCTS | B24: Greenhouse Gas Emissions | C24: FB-AG-110a.1 | D24: 1 | E24: Gross global Scope 1 emissions
B25: Greenhouse Gas Emissions | C25: FB-AG-110a.2 | D25: 0 | E25: Discussion of long-term and short-term strategy or plan to manage Scope 1 emissions, emissions reduction targets, and an analysis of performance against those targets
B26: Greenhouse Gas Emissions | C26: FB-AG-110a.3 | D26: 1 | E26: Fleet fuel consumed, percentage renewable
B27: Energy Management | C27: FB-AG-130a.1 | D27: 1 | E27: (1) Operational energy consumed, (2) percentage grid electricity, (3) percentage renewable
B28: Water Management | C28: FB-AG-140a.1 | D28: 1 | E28: (1) Total water withdrawn, (2) total water consumed, percentage of each in regions with High or Extremely High Baseline Water Stress
B29: Water Management | C29: FB-AG-140a.2 | D29: 0 | E29: Description of water management risks and discussion of strategies and practices to mitigate those risks
B30: Water Management | C30: FB-AG-140a.3 | D30: 1 | E30: Number of incidents of non-compliance associated with water quantity and/or quality permits, standards, and regulations
B31: Food Safety | C31: FB-AG-250a.1 | D31: 1 | E31: Global Food Safety Initiative (GFSI) audit (1) non-conformance rate and (2) associated corrective action rate for (a) major and (b) minor non-conformances
B32: Food Safety | C32: FB-AG-250a.2 | D32: 1 | E32: Percentage of agricultural products sourced from suppliers certified to a Global Food Safety Initiative (GFSI) recognized food safety certification program
B33: Food Safety | C33: FB-AG-250a.3 | D33: 1 | E33: (1) Number of recalls issued and (2) total amount of food product recalled
B34: Workforce Health & Safety | C34: FB-AG-320a.1 | D34: 1 | E34: (1) Total recordable incident rate (TRIR), (2) fatality rate, and (3) near miss frequency rate (NMFR) for (a) direct employees and (b) seasonal and migrant employees
B35: Environmental & Social Impacts of Ingredient Supply Chain | C35: FB-AG-430a.1 | D35: 1 | E35: Percentage of agricultural products sourced that are certified to a third-party environmental and/or social standard, and percentages by standard
B36: Environmental & Social Impacts of Ingredient Supply Chain | C36: FB-AG-430a.2 | D36: 1 | E36: Suppliers’ social and environmental responsibility audit (1) non-conformance rate and (2) associated corrective action rate for (a) major and (b) minor non-conformances
... B40: Ingredient Sourcing | C40: FB-AG-440a.2 | D40: 1 | E40: Percentage of agricultural products sourced from regions with High or Extremely High Baseline Water Stress
A41: AIR FREIGHT & LOGISTICS | B41: Greenhouse Gas Emissions | C41: TR-AF-110a.1 | D41: 1 | E41: Gross global Scope 1 emissions
B42: Greenhouse Gas Emissions | C42: TR-AF-110a.2 | D42: 0 | E42: Discussion of long-term and short-term strategy or plan to manage Scope 1 emissions, emissions reduction targets, and an analysis of performance against those targets
B43: Greenhouse Gas Emissions | C43: TR-AF-110a.3 | D43: 1 | E43: Fuel consumed by (1) road transport, percentage (a) natural gas and (b) renewable, and (2) air transport, percentage (a) alternative and (b) sustainable
...

Sheet List of Sample Metrics
A1: Line in Master | B1: Company | C1: Industry | D1: Code | E1: Metrics | F1: Reported
A2: =Sample!A2 -> 10 | B2: =Sample!B2 -> AdvanSix Inc | C2: CHEMICALS | D2: RT-CH-110a.1 | E2: Gross global Scope 1 emissions, percentage covered under emissions-limiting regulations | F2: 1
D3: RT-CH-110a.2 | E3: Discussion of long-term and short-term strategy or plan to manage Scope 1 emissions, emissions reduction targets, and an analysis of performance against those targets | F3: 1
D4: RT-CH-120a.1 | E4: Air emissions of the following pollutants: (1) NOX (excluding N2O), (2) SOX, (3) volatile organic compounds (VOCs), and (4) hazardous air pollutants (HAPs) | F4: 1
D5: RT-CH-130a.1 | E5: (1) Total energy consumed, (2) percentage grid electricity, (3) percentage renewable, (4) total self-generated energy | F5: 1
D6: RT-CH-140a.1 | E6: (1) Total water withdrawn, (2) total water consumed, percentage of each in regions with High or Extremely High Baseline Water Stress | F6: 1
D7: RT-CH-140a.2 | E7: Number of incidents of non-compliance associated with water quality permits, standards, and regulations | F7: 0
D8: RT-CH-140a.3 | E8: Description of water management risks and discussion of strategies and practices to mitigate those risks | F8: 0
D9: RT-CH-150a.1 | E9: Amount of hazardous waste generated, percentage recycled | F9: 1
D10: RT-CH-210a.1 | E10: Discussion of engagement processes to manage risks and opportunities associated with community interests | F10: 1
D11: RT-CH-320a.1 | E11: (1) Total recordable incident rate (TRIR) and (2) fatality rate for (a) direct employees and (b) contract employees | F11: 1
D12: RT-CH-320a.2 | E12: Description of efforts to assess, monitor, and reduce exposure of employees and contract workers to long-term (chronic) health risks | F12: 1
D13: RT-CH-410a.1 | E13: Revenue from products designed for use-phase resource efficiency | F13: 0
D14: RT-CH-410b.1 | E14: (1) Percentage of products that contain Globally Harmonized System of Classification and Labeling of Chemicals (GHS) Category 1 and 2 Health and Environmental Hazardous Substances, (2) percentage of such products that have undergone a hazard assessment | F14: 0
... D19: RT-CH-540a.2 | E19: Number of transport incidents | F19: 0
A20: =Sample!A3 -> 11 | B20: =Sample!B3 -> Aflac Inc | C20: INSURANCE | D20: FN-IN-270a.1 | E20: Total amount of monetary losses as a result of legal proceedings associated with marketing and communication of insurance product-related information to new and returning customers | F20: 1
D21: FN-IN-270a.2 | E21: Complaints-to-claims ratio | F21: 0
D22: FN-IN-270a.3 | E22: Customer retention rate | F22: 0
D23: FN-IN-270a.4 | E23: Description of approach to informing customers about products | F23: 1
D24: FN-IN-410a.1 | E24: Total invested assets, by industry and asset class | F24: 1
D25: FN-IN-410a.2 | E25: Description of approach to incorporation of environmental, social, and governance (ESG) factors in investment management processes and strategies | F25: 1
D26: FN-IN-410b.1 | E26: Net premiums written related to energy efficiency and low carbon technology | F26: 0
D27: FN-IN-410b.2 | E27: Discussion of products and/or product features that incentivize health, safety, and/or environmentally responsible actions and/or behaviors | F27: 0
D28: FN-IN-450a.1 | E28: Probable Maximum Loss (PML) of insured products from weather-related natural catastrophes | F28: 0
D29: FN-IN-450a.2 | E29: Total amount of monetary losses attributable to insurance payouts from (1) modeled natural catastrophes and (2) non-modeled natural catastrophes, by type of event and geographic segment (net and gross of reinsurance) | F29: 0
D30: FN-IN-450a.3 | E30: Description of approach to incorporation of environmental risks into (1) the underwriting process for individual contracts and (2) the management of firm-level risks and capital adequacy | F30: 0
D31: FN-IN-550a.1 | E31: Exposure to derivative instruments by category: (1) total potential exposure to non-centrally cleared derivatives, (2) total fair value of acceptable collateral posted with the Central Clearinghouse, and (3) total potential exposure to centrally cleared derivatives | F31: 0
D32: FN-IN-550a.2 | E32: Total fair value of securities lending collateral assets | F32: 0
D33: FN-IN-550a.3 | E33: Description of approach to managing capital- and liquidity-related risks associated with systemic non-insurance activities | F33: 0
A34: =Sample!A4 -> 12 | B34: =Sample!B4 -> Agilent Technologies Inc | C34: MEDICAL EQUIPMENT & SUPPLIES | D34: HC-MS-240a.1 | E34: Ratio of weighted average rate of net price increases (for all products) to the annual increase in the U.S. Consumer Price Index | F34: 1
D35: HC-MS-240a.2 | E35: Description of how price information for each product is disclosed to customers or to their agents | F35: 1
D36: HC-MS-250a.1 | E36: Number of recalls issued, total units recalled | F36: 1
D37: HC-MS-250a.2 | E37: List of products listed in the FDA’s MedWatch Safety Alerts for Human Medical Products database | F37: 1
D38: HC-MS-250a.3 | E38: Number of fatalities related to products as reported in the FDA Manufacturer and User Facility Device Experiencedatabase | F38: 1
D39: HC-MS-250a.4 | E39: Number of FDA enforcement actions taken in response to violations of current Good Manufacturing Practices (cGMP), by type | F39: 1
D40: HC-MS-270a.1 | E40: Total amount of monetary losses as a result of legal proceedings associated with bribery or corruption | F40: 1
D41: HC-MS-270a.2 | E41: Description of code of ethics governing promotion of off-label use of products | F41: 1
D42: HC-MS-410a.1 | E42: Discussion of process to assess and manage environmental and human health considerations associated with chemicals in products, and meet demand for sustainable products | F42: 1
D43: HC-MS-410a.2 | E43: Total amount of products accepted for take-back and reused, recycled, or donated, broken down by: (1) devices and equipment and (2) supplies | F43: 1
D44: HC-MS-430a.1 | E44: Percentage of (1) entity's facilities and (2) Tier I suppliers' facilities participating in third-party audit programs for manufacturing and product quality | F44: 1
...

Sheet List of Sample Metrics (fill)
A1: Line in Master | B1: Company | C1: Industry | D1: Code | E1: Metrics | F1: Reported | G1: Disclosed Information | H1: Reason Summary
A2: 10 | B2: AdvanSix Inc | C2: CHEMICALS | D2: RT-CH-110a.1 | E2: Gross global Scope 1 emissions, percentage covered under emissions-limiting regulations | F2: 1
A3: 10 | B3: AdvanSix Inc | C3: CHEMICALS | D3: RT-CH-110a.2 | E3: Discussion of long-term and short-term strategy or plan to manage Scope 1 emissions, emissions reduction targets, and an analysis of performance against those targets | F3: 1
A4: 10 | B4: AdvanSix Inc | C4: CHEMICALS | D4: RT-CH-120a.1 | E4: Air emissions of the following pollutants: (1) NOX (excluding N2O), (2) SOX, (3) volatile organic compounds (VOCs), and (4) hazardous air pollutants (HAPs) | F4: 1
A5: 10 | B5: AdvanSix Inc | C5: CHEMICALS | D5: RT-CH-130a.1 | E5: (1) Total energy consumed, (2) percentage grid electricity, (3) percentage renewable, (4) total self-generated energy | F5: 1
A6: 10 | B6: AdvanSix Inc | C6: CHEMICALS | D6: RT-CH-140a.1 | E6: (1) Total water withdrawn, (2) total water consumed, percentage of each in regions with High or Extremely High Baseline Water Stress | F6: 1
A7: 10 | B7: AdvanSix Inc | C7: CHEMICALS | D7: RT-CH-140a.2 | E7: Number of incidents of non-compliance associated with water quality permits, standards, and regulations | F7: 0 | G7: N/A
A8: 10 | B8: AdvanSix Inc | C8: CHEMICALS | D8: RT-CH-140a.3 | E8: Description of water management risks and discussion of strategies and practices to mitigate those risks | F8: 0 | G8: N/A
A9: 10 | B9: AdvanSix Inc | C9: CHEMICALS | D9: RT-CH-150a.1 | E9: Amount of hazardous waste generated, percentage recycled | F9: 1
A10: 10 | B10: AdvanSix Inc | C10: CHEMICALS | D10: RT-CH-210a.1 | E10: Discussion of engagement processes to manage risks and opportunities associated with community interests | F10: 1
A11: 10 | B11: AdvanSix Inc | C11: CHEMICALS | D11: RT-CH-320a.1 | E11: (1) Total recordable incident rate (TRIR) and (2) fatality rate for (a) direct employees and (b) contract employees | F11: 1
A12: 10 | B12: AdvanSix Inc | C12: CHEMICALS | D12: RT-CH-320a.2 | E12: Description of efforts to assess, monitor, and reduce exposure of employees and contract workers to long-term (chronic) health risks | F12: 1
A13: 10 | B13: AdvanSix Inc | C13: CHEMICALS | D13: RT-CH-410a.1 | E13: Revenue from products designed for use-phase resource efficiency | F13: 0 | G13: N/A
A14: 10 | B14: AdvanSix Inc | C14: CHEMICALS | D14: RT-CH-410b.1 | E14: (1) Percentage of products that contain Globally Harmonized System of Classification and Labeling of Chemicals (GHS) Category 1 and 2 Health and Environmental Hazardous Substances, (2) percentage of such products that have undergone a hazard assessment | F14: 0 | G14: N/A
A15: 10 | B15: AdvanSix Inc | C15: CHEMICALS | D15: RT-CH-410b.2 | E15: Discussion of strategy to (1) manage chemicals of concern and (2) develop alternatives with reduced human and/or environmental impact | F15: 1
A16: 10 | B16: AdvanSix Inc | C16: CHEMICALS | D16: RT-CH-410c.1 | E16: Percentage of products by revenue that contain genetically modified organisms (GMOs) | F16: 0 | G16: N/A
A17: 10 | B17: AdvanSix Inc | C17: CHEMICALS | D17: RT-CH-530a.1 | E17: Discussion of corporate positions related to government regulations and/or policy proposals that address environmental and social factors affecting the industry | F17: 1
A18: 10 | B18: AdvanSix Inc | C18: CHEMICALS | D18: RT-CH-540a.1 | E18: Process Safety Incidents Count (PSIC), Process Safety Total Incident Rate (PSTIR), and Process Safety Incident Severity Rate (PSISR) | F18: 1
A19: 10 | B19: AdvanSix Inc | C19: CHEMICALS | D19: RT-CH-540a.2 | E19: Number of transport incidents | F19: 0 | G19: N/A
A20: 11 | B20: Aflac Inc | C20: INSURANCE | D20: FN-IN-270a.1 | E20: Total amount of monetary losses as a result of legal proceedings associated with marketing and communication of insurance product-related information to new and returning customers | F20: 1
A21: 11 | B21: Aflac Inc | C21: INSURANCE | D21: FN-IN-270a.2 | E21: Complaints-to-claims ratio | F21: 0 | G21: N/A
A22: 11 | B22: Aflac Inc | C22: INSURANCE | D22: FN-IN-270a.3 | E22: Customer retention rate | F22: 0 | G22: N/A
A23: 11 | B23: Aflac Inc | C23: INSURANCE | D23: FN-IN-270a.4 | E23: Description of approach to informing customers about products | F23: 1
A24: 11 | B24: Aflac Inc | C24: INSURANCE | D24: FN-IN-410a.1 | E24: Total invested assets, by industry and asset class | F24: 1
A25: 11 | B25: Aflac Inc | C25: INSURANCE | D25: FN-IN-410a.2 | E25: Description of approach to incorporation of environmental, social, and governance (ESG) factors in investment management processes and strategies | F25: 1
A26: 11 | B26: Aflac Inc | C26: INSURANCE | D26: FN-IN-410b.1 | E26: Net premiums written related to energy efficiency and low carbon technology | F26: 0 | G26: N/A
A27: 11 | B27: Aflac Inc | C27: INSURANCE | D27: FN-IN-410b.2 | E27: Discussion of products and/or product features that incentivize health, safety, and/or environmentally responsible actions and/or behaviors | F27: 0 | G27: N/A
A28: 11 | B28: Aflac Inc | C28: INSURANCE | D28: FN-IN-450a.1 | E28: Probable Maximum Loss (PML) of insured products from weather-related natural catastrophes | F28: 0 | G28: N/A
A29: 11 | B29: Aflac Inc | C29: INSURANCE | D29: FN-IN-450a.2 | E29: Total amount of monetary losses attributable to insurance payouts from (1) modeled natural catastrophes and (2) non-modeled natural catastrophes, by type of event and geographic segment (net and gross of reinsurance) | F29: 0 | G29: N/A
A30: 11 | B30: Aflac Inc | C30: INSURANCE | D30: FN-IN-450a.3 | E30: Description of approach to incorporation of environmental risks into (1) the underwriting process for individual contracts and (2) the management of firm-level risks and capital adequacy | F30: 0 | G30: N/A
A31: 11 | B31: Aflac Inc | C31: INSURANCE | D31: FN-IN-550a.1 | E31: Exposure to derivative instruments by category: (1) total potential exposure to non-centrally cleared derivatives, (2) total fair value of acceptable collateral posted with the Central Clearinghouse, and (3) total potential exposure to centrally cleared derivatives | F31: 0 | G31: N/A
A32: 11 | B32: Aflac Inc | C32: INSURANCE | D32: FN-IN-550a.2 | E32: Total fair value of securities lending collateral assets | F32: 0 | G32: N/A
A33: 11 | B33: Aflac Inc | C33: INSURANCE | D33: FN-IN-550a.3 | E33: Description of approach to managing capital- and liquidity-related risks associated with systemic non-insurance activities | F33: 0 | G33: N/A
A34: 12 | B34: Agilent Technologies Inc | C34: MEDICAL EQUIPMENT & SUPPLIES | D34: HC-MS-240a.1 | E34: Ratio of weighted average rate of net price increases (for all products) to the annual increase in the U.S. Consumer Price Index | F34: 1
A35: 12 | B35: Agilent Technologies Inc | C35: MEDICAL EQUIPMENT & SUPPLIES | D35: HC-MS-240a.2 | E35: Description of how price information for each product is disclosed to customers or to their agents | F35: 1
A36: 12 | B36: Agilent Technologies Inc | C36: MEDICAL EQUIPMENT & SUPPLIES | D36: HC-MS-250a.1 | E36: Number of recalls issued, total units recalled | F36: 1
A37: 12 | B37: Agilent Technologies Inc | C37: MEDICAL EQUIPMENT & SUPPLIES | D37: HC-MS-250a.2 | E37: List of products listed in the FDAâ€™s MedWatch Safety Alerts for Human Medical Products database | F37: 1
A38: 12 | B38: Agilent Technologies Inc | C38: MEDICAL EQUIPMENT & SUPPLIES | D38: HC-MS-250a.3 | E38: Number of fatalities related to products as reported in the FDA Manufacturer and User Facility Device Experiencedatabase | F38: 1
A39: 12 | B39: Agilent Technologies Inc | C39: MEDICAL EQUIPMENT & SUPPLIES | D39: HC-MS-250a.4 | E39: Number of FDA enforcement actions taken in response to violations of current Good Manufacturing Practices (cGMP), by type | F39: 1
A40: 12 | B40: Agilent Technologies Inc | C40: MEDICAL EQUIPMENT & SUPPLIES | D40: HC-MS-270a.1 | E40: Total amount of monetary losses as a result of legal proceedings associated with bribery or corruption | F40: 1
...

Sheet Losses
A1: Line in Master | B1: Company | C1: Industry | D1: Code | E1: Reported | F1: Topics | G1: Metrics | H1: code_ind1 | I1: code_ind2 | J1: code_topic | K1: ind_code | L1: Disclosed Amount | M1: Violation Tracker | N1: Date | O1: Primary Offense Type | P1: Violation Description | Q1: Agency | R1: Amount | S1: Link
A2: 11 | B2: Aflac Inc | C2: INSURANCE | D2: FN-IN-270a.1 | E2: 1 | F2: Transparent Information & Fair Advice for Customers | G2: Total amount of monetary losses as a result of legal proceedings associated with marketing and communication of insurance product-related information to new and returning customers | H2: FN | I2: IN | J2: 270 | K2: FN-IN | L2: Refered to 10K/Q | M2: No
A3: 11 | B3: Aflac Inc | C3: INSURANCE | D3: FN-IN-450a.2 | E3: 0 | F3: Environmental Risk Exposure | G3: Total amount of monetary losses attributable to insurance payouts from (1) modeled natural catastrophes and (2) non-modeled natural catastrophes, by type of event and geographic segment (net and gross of reinsurance) | H3: FN | I3: IN | J3: 450 | K3: FN-IN | L3: Refered to 10K/Q | M3: No
A4: 12 | B4: Agilent Technologies Inc | C4: MEDICAL EQUIPMENT & SUPPLIES | D4: HC-MS-270a.1 | E4: 1 | F4: Ethical Marketing | G4: Total amount of monetary losses as a result of legal proceedings associated with false marketing claims | H4: HC | I4: MS | J4: 270 | K4: HC-MS | L4: 0 | M4: No
A5: 12 | B5: Agilent Technologies Inc | C5: MEDICAL EQUIPMENT & SUPPLIES | D5: HC-MS-510a.1 | E5: 1 | F5: Business Ethics | G5: Total amount of monetary losses as a result of legal proceedings associated with bribery or corruption | H5: HC | I5: MS | J5: 510 | K5: HC-MS | L5: 0 | M5: No
A6: 14 | B6: AGNC Investment Corp | C6: ASSET MANAGEMENT & CUSTODY | D6: FN-AC-510a.1 | E6: 1 | F6: Business Ethics | G6: Total amount of monetary losses as a result of legal proceedings associated with fraud, insider trading, anti-trust, anti-competitive behavior, market manipulation, malpractice, or other related financial industry laws or regulations | H6: FN | I6: AC | J6: 510 | K6: FN-AC | L6: 0 | M6: No
A7: 14 | B7: AGNC Investment Corp | C7: ASSET MANAGEMENT & CUSTODY | D7: FN-AC-270a.2 | E7: 1 | F7: Transparent Information & Fair Advice for Customers | G7: Total amount of monetary losses as a result of legal proceedings associated with marketing and communication of financial product-related information to new and returning customers | H7: FN | I7: AC | J7: 270 | K7: FN-AC | L7: 0 | M7: No
A8: 15 | B8: AIG - American International Group Inc | C8: INSURANCE | D8: FN-IN-450a.2 | E8: 1 | F8: Environmental Risk Exposure | G8: Total amount of monetary losses attributable to insurance payouts from (1) modeled natural catastrophes and (2) non-modeled natural catastrophes, by type of event and geographic segment (net and gross of reinsurance) | H8: FN | I8: IN | J8: 450 | K8: FN-IN | L8: 0 | M8: No
A9: 15 | B9: AIG - American International Group Inc | C9: INSURANCE | D9: FN-IN-270a.1 | E9: 0 | F9: Transparent Information & Fair Advice for Customers | G9: Total amount of monetary losses as a result of legal proceedings associated with marketing and communication of insurance product-related information to new and returning customers | H9: FN | I9: IN | J9: 270 | K9: FN-IN | M9: No
A10: 15 | B10: AIG - American International Group Inc | C10: ASSET MANAGEMENT & CUSTODY | D10: FN-AC-510a.1 | E10: 0 | F10: Business Ethics | G10: Total amount of monetary losses as a result of legal proceedings associated with fraud, insider trading, anti-trust, anti-competitive behavior, market manipulation, malpractice, or other related financial industry laws or regulations | H10: FN | I10: AC | J10: 510 | K10: FN-AC | M10: No
A11: 15 | B11: AIG - American International Group Inc | C11: ASSET MANAGEMENT & CUSTODY | D11: FN-AC-270a.2 | E11: 0 | F11: Transparent Information & Fair Advice for Customers | G11: Total amount of monetary losses as a result of legal proceedings associated with marketing and communication of financial product-related information to new and returning customers | H11: FN | I11: AC | J11: 270 | K11: FN-AC | M11: No
A12: 17 | B12: Akamai Technologies Inc | C12: SOFTWARE & IT SERVICES | D12: TC-SI-220a.3 | E12: 0 | F12: Data Privacy & Freedom of Expression | G12: Total amount of monetary losses as a result of legal proceedings associated with user privacy | H12: TC | I12: SI | J12: 220 | K12: TC-SI | M12: No
A13: 17 | B13: Akamai Technologies Inc | C13: SOFTWARE & IT SERVICES | D13: TC-SI-520a.1 | E13: 0 | F13: Intellectual Property Protection & Competitive Behavior | G13: Total amount of monetary losses as a result of legal proceedings associated with anti-competitive behavior regulations | H13: TC | I13: SI | J13: 520 | K13: TC-SI | M13: No
A14: 27 | B14: Alliance Data Systems Corp | C14: COMMERCIAL BANKS | D14: FN-CB-510a.1 | E14: 1 | F14: Business Ethics | G14: Total amount of monetary losses as a result of legal proceedings associated with fraud, insider trading, anti-trust, anti-competitive behavior, market manipulation, malpractice, or other related financial industry laws or regulations | H14: FN | I14: CB | J14: 510 | K14: FN-CB | M14: No
A15: 27 | B15: Alliance Data Systems Corp | C15: SOFTWARE & IT SERVICES | D15: TC-SI-220a.3 | E15: 0 | F15: Data Privacy & Freedom of Expression | G15: Total amount of monetary losses as a result of legal proceedings associated with user privacy | H15: TC | I15: SI | J15: 220 | K15: TC-SI | M15: No
A16: 27 | B16: Alliance Data Systems Corp | C16: SOFTWARE & IT SERVICES | D16: TC-SI-520a.1 | E16: 0 | F16: Intellectual Property Protection & Competitive Behavior | G16: Total amount of monetary losses as a result of legal proceedings associated with anti-competitive behavior regulations | H16: TC | I16: SI | J16: 520 | K16: TC-SI | M16: No
A17: 28 | B17: Alliance Data Systems Corp | C17: COMMERCIAL BANKS | D17: FN-CB-510a.1 | E17: 1 | F17: Business Ethics | G17: Total amount of monetary losses as a result of legal proceedings associated with fraud, insider trading, anti-trust, anti-competitive behavior, market manipulation, malpractice, or other related financial industry laws or regulations | H17: FN | I17: CB | J17: 510 | K17: FN-CB | M17: No
A18: 28 | B18: Alliance Data Systems Corp | C18: SOFTWARE & IT SERVICES | D18: TC-SI-220a.3 | E18: 0 | F18: Data Privacy & Freedom of Expression | G18: Total amount of monetary losses as a result of legal proceedings associated with user privacy | H18: TC | I18: SI | J18: 220 | K18: TC-SI | M18: No
A19: 28 | B19: Alliance Data Systems Corp | C19: SOFTWARE & IT SERVICES | D19: TC-SI-520a.1 | E19: 0 | F19: Intellectual Property Protection & Competitive Behavior | G19: Total amount of monetary losses as a result of legal proceedings associated with anti-competitive behavior regulations | H19: TC | I19: SI | J19: 520 | K19: TC-SI | M19: No
A20: 36 | B20: American Airlines Group Inc | C20: AIRLINES | D20: TR-AL-520a.1 | E20: 1 | F20: Competitive Behavior | G20: Total amount of monetary losses as a result of legal proceedings associated with anti-competitive behavior regulations | H20: TR | I20: AL | J20: 520 | K20: TR-AL | L20: 0 | M20: Yes | N20: 43598 | O20: price-fixing or anti-competitive practices | Q20: private lawsuit-federal | R20: 45000000 | S20: https://violationtracker.goodjobsfirst.org/violation-tracker/-american-airlines-20
A21: 39 | B21: American Express Co | C21: CONSUMER FINANCE | D21: FN-CF-220a.2 | E21: 1 | F21: Customer Privacy | G21: Total amount of monetary losses as a result of legal proceedings associated with customer privacy | H21: FN | I21: CF | J21: 220 | K21: FN-CF | L21: 0 | M21: No
A22: 39 | B22: American Express Co | C22: CONSUMER FINANCE | D22: FN-CF-270a.4 | E22: 1 | F22: Selling Practices | G22: (1) Number of complaints filed with the Consumer Financial Protection Bureau (CFPB), (2) percentage with monetary or non-monetary relief, (3) percentage disputed by consumer, (4) percentage that resulted in investigation by the CFPB | H22: FN | I22: CF | J22: 270 | K22: FN-CF | L22: 0 | M22: No
A23: 39 | B23: American Express Co | C23: CONSUMER FINANCE | D23: FN-CF-270a.5 | E23: 1 | F23: Selling Practices | G23: Total amount of monetary losses as a result of legal proceedings associated with selling and servicing of products | H23: FN | I23: CF | J23: 270 | K23: FN-CF | L23: 0 | M23: No
A24: 39 | B24: American Express Co | C24: COMMERCIAL BANKS | D24: FN-CB-510a.1 | E24: 1 | F24: Business Ethics | G24: Total amount of monetary losses as a result of legal proceedings associated with fraud, insider trading, anti-trust, anti-competitive behavior, market manipulation, malpractice, or other related financial industry laws or regulations | H24: FN | I24: CB | J24: 510 | K24: FN-CB | L24: 0 | M24: No
A25: 39 | B25: American Express Co | C25: SOFTWARE & IT SERVICES | D25: TC-SI-220a.3 | E25: 1 | F25: Data Privacy & Freedom of Expression | G25: Total amount of monetary losses as a result of legal proceedings associated with user privacy | H25: TC | I25: SI | J25: 220 | K25: TC-SI | L25: 0 | M25: No
A26: 39 | B26: American Express Co | C26: SOFTWARE & IT SERVICES | D26: TC-SI-520a.1 | E26: 1 | F26: Intellectual Property Protection & Competitive Behavior | G26: Total amount of monetary losses as a result of legal proceedings associated with anti-competitive behavior regulations | H26: TC | I26: SI | J26: 520 | K26: TC-SI | L26: 0 | M26: No
A27: 42 | B27: American Tower Corp | C27: TELECOMMUNICATION SERVICES | D27: TC-TL-520a.1 | E27: 1 | F27: Competitive Behavior & Open Internet | G27: Total amount of monetary losses as a result of legal proceedings associated with anti-competitive behavior regulations | H27: TC | I27: TL | J27: 520 | K27: TC-TL | L27: 0 | M27: No
A28: 42 | B28: American Tower Corp | C28: TELECOMMUNICATION SERVICES | D28: TC-TL-220a.3 | E28: 0 | F28: Data Privacy | G28: Total amount of monetary losses as a result of legal proceedings associated with customer privacy | H28: TC | I28: TL | J28: 220 | K28: TC-TL | L28: 0 | M28: No
A29: 48 | B29: Amphenol Corp | C29: ELECTRICAL & ELECTRONIC EQUIPMENT | D29: RT-EE-510a.2 | E29: 1 | F29: Business Ethics | G29: Total amount of monetary losses as a result of legal proceedings associated with bribery or corruption | H29: RT | I29: EE | J29: 510 | K29: RT-EE | L29: 0 | M29: No
