Workbook

Sheet Supply 2024
B1: Commodities/Industries | C1: 111CA | D1: 113FF | E1: 211 | F1: 212 | G1: 213 | H1: 22 | I1: 23 | J1: 321 | K1: 327 | L1: 331 | M1: 332 | N1: 333 | O1: 334 | P1: 335 | Q1: 3361MV | R1: 3364OT | S1: 337 | T1: 339 | U1: 311FT | V1: 313TT | W1: 315AL | X1: 322 | Y1: 323 | Z1: 324 | AA1: 325 | AB1: 326 | AC1: 42 | AD1: 441 | AE1: 445 | AF1: 452 | AG1: 4A0 | AH1: 481 | AI1: 482 | AJ1: 483 | AK1: 484 | AL1: 485 | AM1: 486 | AN1: 487OS | AO1: 493 | AP1: 511 | AQ1: 512 | AR1: 513 | AS1: 514 | AT1: 521CI | AU1: 523 | AV1: 524 | AW1: 525 | AX1: HS | AY1: ORE | AZ1: 532RL | BA1: 5411 | BB1: 5415 | BC1: 5412OP | BD1: 55 | BE1: 561 | BF1: 562 | BG1: 61 | BH1: 621 | BI1: 622 | BJ1: 623 | BK1: 624 | BL1: 711AS | BM1: 713 | BN1: 721 | BO1: 722 | BP1: 81 | BQ1: GFGD | BR1: GFGN | BS1: GFE | BT1: GSLG | BU1: GSLE | BV1: T007 | BW1: MCIF | BX1: MADJ | BY1: T013 | BZ1: Trade | CA1: Trans | CB1: T014 | CC1: MDTY | CD1: TOP | CE1: SUB | CF1: T015 | CG1: T016
A2: IOCode | B2: Name | C2: Farms | D2: Forestry, fishing, and related activities | E2: Oil and gas extraction | F2: Mining, except oil and gas | G2: Support activities for mining | H2: Utilities | I2: Construction | J2: Wood products | K2: Nonmetallic mineral products | L2: Primary metals | M2: Fabricated metal products | N2: Machinery | O2: Computer and electronic products | P2: Electrical equipment, appliances, and components | Q2: Motor vehicles, bodies and trailers, and parts | R2: Other transportation equipment | S2: Furniture and related products | T2: Miscellaneous manufacturing | U2: Food and beverage and tobacco products | V2: Textile mills and textile product mills | W2: Apparel and leather and allied products | X2: Paper products | Y2: Printing and related support activities | Z2: Petroleum and coal products | AA2: Chemical products | AB2: Plastics and rubber products | AC2: Wholesale trade | AD2: Motor vehicle and parts dealers | AE2: Food and beverage stores | AF2: General merchandise stores | AG2: Other retail | AH2: Air transportation | AI2: Rail transportation | AJ2: Water transportation | AK2: Truck transportation | AL2: Transit and ground passenger transportation | AM2: Pipeline transportation | AN2: Other transportation and support activities | AO2: Warehousing and storage | AP2: Publishing industries, except internet (includes software) | AQ2: Motion picture and sound recording industries | AR2: Broadcasting and telecommunications | AS2: Data processing, internet publishing, and other information services | AT2: Federal Reserve banks, credit intermediation, and related activities | AU2: Securities, commodity contracts, and investments | AV2: Insurance carriers and related activities | AW2: Funds, trusts, and other financial vehicles | AX2: Housing | AY2: Other real estate | AZ2: Rental and leasing services and lessors of intangible assets | BA2: Legal services | BB2: Computer systems design and related services | BC2: Miscellaneous professional, scientific, and technical services | BD2: Management of companies and enterprises | BE2: Administrative and support services | BF2: Waste management and remediation services | BG2: Educational services | BH2: Ambulatory health care services | BI2: Hospitals | BJ2: Nursing and residential care facilities | BK2: Social assistance | BL2: Performing arts, spectator sports, museums, and related activities | BM2: Amusements, gambling, and recreation industries | BN2: Accommodation | BO2: Food services and drinking places | BP2: Other services, except government | BQ2: Federal general government (defense) | BR2: Federal general government (nondefense) | BS2: Federal government enterprises | BT2: State and local general government | BU2: State and local government enterprises | BV2: Total Commodity Output | BW2: Imports | BX2: CIF/FOB Adjustments on Imports | BY2: Total product supply (basic prices) | BZ2: Trade margins | CA2: Transport margins | CB2: Total trade and transportation margins | CC2: Import duties | CD2: Tax on products | CE2: Subsidies | CF2: Total tax less subsidies on products | CG2: Total product supply (purchaser prices)
A3: 111CA | B3: Farms | C3: 562960 | D3: 30 | E3: 0 | F3: 0 | G3: 0 | H3: 0 | I3: 0 | J3: 0 | K3: 0 | L3: 0 | M3: 0 | N3: 0 | O3: 0 | P3: 0 | Q3: 0 | R3: 0 | S3: 0 | T3: 0 | U3: 0 | V3: 0 | W3: 0 | X3: 0 | Y3: 0 | Z3: 0 | AA3: 0 | AB3: 0 | AC3: 0 | AD3: 0 | AE3: 0 | AF3: 0 | AG3: 300 | AH3: 0 | AI3: 0 | AJ3: 0 | AK3: 0 | AL3: 0 | AM3: 0 | AN3: 0 | AO3: 0 | AP3: 0 | AQ3: 0 | AR3: 0 | AS3: 0 | AT3: 0 | AU3: 0 | AV3: 0 | AW3: 0 | AX3: 0 | AY3: 0 | AZ3: 0 | BA3: 0 | BB3: 0 | BC3: 0 | BD3: 0 | BE3: 0 | BF3: 0 | BG3: 0 | BH3: 0 | BI3: 0 | BJ3: 0 | BK3: 0 | BL3: 0 | BM3: 0 | BN3: 0 | BO3: 0 | BP3: 0 | BQ3: 0 | BR3: 0 | BS3: 0 | BT3: 772 | BU3: 0 | BV3: 564063 | BW3: 60403 | BX3: 0 | BY3: 624466 | BZ3: 175628 | CA3: 79143 | CB3: 254771 | CC3: 181 | CD3: 11502 | CE3: -7036 | CF3: 4648 | CG3: 883884
A4: 113FF | B4: Forestry, fishing, and related activities | C4: 7051 | D4: 66127 | E4: 0 | F4: 0 | G4: 0 | H4: 0 | I4: 0 | J4: 0 | K4: 0 | L4: 0 | M4: 0 | N4: 0 | O4: 0 | P4: 0 | Q4: 0 | R4: 0 | S4: 0 | T4: 0 | U4: 0 | V4: 0 | W4: 0 | X4: 0 | Y4: 0 | Z4: 0 | AA4: 0 | AB4: 0 | AC4: 103 | AD4: 0 | AE4: 0 | AF4: 0 | AG4: 0 | AH4: 987 | AI4: 0 | AJ4: 0 | AK4: 0 | AL4: 0 | AM4: 0 | AN4: 0 | AO4: 0 | AP4: 0 | AQ4: 0 | AR4: 0 | AS4: 0 | AT4: 0 | AU4: 0 | AV4: 0 | AW4: 0 | AX4: 0 | AY4: 0 | AZ4: 0 | BA4: 0 | BB4: 0 | BC4: 0 | BD4: 0 | BE4: 0 | BF4: 0 | BG4: 0 | BH4: 0 | BI4: 0 | BJ4: 0 | BK4: 0 | BL4: 0 | BM4: 0 | BN4: 0 | BO4: 0 | BP4: 0 | BQ4: 0 | BR4: -18 | BS4: 0 | BT4: 4489 | BU4: 0 | BV4: 78738 | BW4: 19527 | BX4: 0 | BY4: 98265 | BZ4: 13577 | CA4: 4933 | CB4: 18510 | CC4: 195 | CD4: 1427 | CE4: 0 | CF4: 1622 | CG4: 118398
A5: 211 | B5: Oil and gas extraction | C5: 0 | D5: 0 | E5: 373547 | F5: 0 | G5: 361 | H5: 130 | I5: 0 | J5: 0 | K5: 0 | L5: 0 | M5: 0 | N5: 0 | O5: 0 | P5: 0 | Q5: 0 | R5: 0 | S5: 0 | T5: 0 | U5: 0 | V5: 0 | W5: 0 | X5: 0 | Y5: 0 | Z5: 1 | AA5: 0 | AB5: 0 | AC5: 0 | AD5: 0 | AE5: 0 | AF5: 0 | AG5: 0 | AH5: 0 | AI5: 0 | AJ5: 0 | AK5: 0 | AL5: 0 | AM5: 0 | AN5: 0 | AO5: 0 | AP5: 0 | AQ5: 0 | AR5: 0 | AS5: 0 | AT5: 0 | AU5: 0 | AV5: 0 | AW5: 0 | AX5: 0 | AY5: 0 | AZ5: 0 | BA5: 0 | BB5: 0 | BC5: 0 | BD5: 0 | BE5: 0 | BF5: 352 | BG5: 0 | BH5: 0 | BI5: 0 | BJ5: 0 | BK5: 0 | BL5: 0 | BM5: 0 | BN5: 0 | BO5: 0 | BP5: 0 | BQ5: 0 | BR5: 0 | BS5: 0 | BT5: 0 | BU5: 0 | BV5: 374390 | BW5: 173685 | BX5: 0 | BY5: 548074 | BZ5: 23266 | CA5: 71063 | CB5: 94328 | CC5: 144 | CD5: 18412 | CE5: 0 | CF5: 18556 | CG5: 660959
A6: 212 | B6: Mining, except oil and gas | C6: 0 | D6: 0 | E6: 55 | F6: 104868 | G6: 0 | H6: 0 | I6: 0 | J6: 0 | K6: 759 | L6: 0 | M6: 0 | N6: 0 | O6: 0 | P6: 0 | Q6: 0 | R6: 0 | S6: 0 | T6: 0 | U6: 0 | V6: 0 | W6: 0 | X6: 0 | Y6: 0 | Z6: 58 | AA6: 0 | AB6: 0 | AC6: 0 | AD6: 0 | AE6: 0 | AF6: 0 | AG6: 0 | AH6: 0 | AI6: 0 | AJ6: 0 | AK6: 0 | AL6: 0 | AM6: 0 | AN6: 0 | AO6: 0 | AP6: 0 | AQ6: 0 | AR6: 0 | AS6: 0 | AT6: 0 | AU6: 0 | AV6: 0 | AW6: 0 | AX6: 0 | AY6: 0 | AZ6: 0 | BA6: 0 | BB6: 0 | BC6: 0 | BD6: 0 | BE6: 0 | BF6: 0 | BG6: 0 | BH6: 0 | BI6: 0 | BJ6: 0 | BK6: 0 | BL6: 0 | BM6: 0 | BN6: 0 | BO6: 0 | BP6: 0 | BQ6: 0 | BR6: 0 | BS6: 0 | BT6: 941 | BU6: 0 | BV6: 106680 | BW6: 6198 | BX6: 0 | BY6: 112878 | BZ6: 10067 | CA6: 33390 | CB6: 43457 | CC6: 11 | CD6: 5076 | CE6: 0 | CF6: 5087 | CG6: 161422
A7: 213 | B7: Support activities for mining | C7: 0 | D7: 0 | E7: 17655 | F7: 9699 | G7: 101890 | H7: 0 | I7: 0 | J7: 0 | K7: 0 | L7: 0 | M7: 0 | N7: 7 | O7: 0 | P7: 0 | Q7: 0 | R7: 0 | S7: 0 | T7: 0 | U7: 0 | V7: 0 | W7: 0 | X7: 0 | Y7: 0 | Z7: 0 | AA7: 0 | AB7: 0 | AC7: 0 | AD7: 0 | AE7: 0 | AF7: 0 | AG7: 0 | AH7: 0 | AI7: 0 | AJ7: 0 | AK7: 0 | AL7: 0 | AM7: 0 | AN7: 0 | AO7: 0 | AP7: 0 | AQ7: 0 | AR7: 0 | AS7: 0 | AT7: 0 | AU7: 0 | AV7: 0 | AW7: 0 | AX7: 0 | AY7: 0 | AZ7: 0 | BA7: 0 | BB7: 0 | BC7: 0 | BD7: 0 | BE7: 0 | BF7: 0 | BG7: 0 | BH7: 0 | BI7: 0 | BJ7: 0 | BK7: 0 | BL7: 0 | BM7: 0 | BN7: 0 | BO7: 0 | BP7: 0 | BQ7: 0 | BR7: 0 | BS7: 0 | BT7: 0 | BU7: 0 | BV7: 129251 | BW7: 2485 | BX7: 0 | BY7: 131737 | BZ7: 0 | CA7: 0 | CB7: 0 | CC7: 0 | CD7: 0 | CE7: 0 | CF7: 0 | CG7: 131737
A8: 22 | B8: Utilities | C8: 0 | D8: 0 | E8: 0 | F8: 0 | G8: 0 | H8: 585445 | I8: 0 | J8: 0 | K8: 0 | L8: 0 | M8: 0 | N8: 0 | O8: 0 | P8: 0 | Q8: 0 | R8: 0 | S8: 0 | T8: 0 | U8: 0 | V8: 0 | W8: 0 | X8: 0 | Y8: 0 | Z8: 0 | AA8: 0 | AB8: 0 | AC8: 0 | AD8: 0 | AE8: 0 | AF8: 0 | AG8: 0 | AH8: 0 | AI8: 0 | AJ8: 0 | AK8: 0 | AL8: 0 | AM8: 237 | AN8: 0 | AO8: 0 | AP8: 0 | AQ8: 0 | AR8: 0 | AS8: 0 | AT8: 0 | AU8: 0 | AV8: 0 | AW8: 0 | AX8: 0 | AY8: 0 | AZ8: 0 | BA8: 0 | BB8: 0 | BC8: 0 | BD8: 0 | BE8: 0 | BF8: 0 | BG8: 0 | BH8: 0 | BI8: 0 | BJ8: 0 | BK8: 0 | BL8: 0 | BM8: 0 | BN8: 0 | BO8: 0 | BP8: 0 | BQ8: 0 | BR8: -9 | BS8: 18120 | BT8: 1645 | BU8: 185989 | BV8: 791427 | BW8: 2489 | BX8: 0 | BY8: 793916 | BZ8: 0 | CA8: 0 | CB8: 0 | CC8: 0 | CD8: 40202 | CE8: 0 | CF8: 40202 | CG8: 834117
A9: 23 | B9: Construction | C9: 0 | D9: 1054 | E9: 280 | F9: 17463 | G9: 6877 | H9: 3771 | I9: 2507925 | J9: 2065 | K9: 2810 | L9: 716 | M9: 5516 | N9: 1544 | O9: 166 | P9: 242 | Q9: 1609 | R9: 2527 | S9: 1199 | T9: 961 | U9: 514 | V9: 128 | W9: 5 | X9: 280 | Y9: 49 | Z9: 814 | AA9: 463 | AB9: 375 | AC9: 8977 | AD9: 11 | AE9: 0 | AF9: 1982 | AG9: 5673 | AH9: 38 | AI9: 25 | AJ9: 0 | AK9: 23 | AL9: 0 | AM9: 106 | AN9: 105 | AO9: 120 | AP9: 25 | AQ9: 89 | AR9: 1463 | AS9: 998 | AT9: 4 | AU9: 2 | AV9: 5 | AW9: 0 | AX9: 29504 | AY9: 351 | AZ9: 89 | BA9: 2 | BB9: 10 | BC9: 726 | BD9: 96 | BE9: 1582 | BF9: 4 | BG9: 888 | BH9: 1057 | BI9: 1617 | BJ9: 42 | BK9: 152 | BL9: 748 | BM9: 693 | BN9: 1332 | BO9: 1301 | BP9: 673 | BQ9: 3 | BR9: 365 | BS9: 0 | BT9: 31257 | BU9: 0 | BV9: 2651493 | BW9: 0 | BX9: 0 | BY9: 2651493 | BZ9: 0 | CA9: 0 | CB9: 0 | CC9: 0 | CD9: 3084 | CE9: 0 | CF9: 3084 | CG9: 2654577
A10: 321 | B10: Wood products | C10: 12 | D10: 0 | E10: 0 | F10: 0 | G10: 0 | H10: 0 | I10: 0 | J10: 167883 | K10: 23 | L10: 0 | M10: 268 | N10: 0 | O10: 0 | P10: 0 | Q10: 0 | R10: 0 | S10: 584 | T10: 101 | U10: 0 | V10: 0 | W10: 0 | X10: 219 | Y10: 19 | Z10: 0 | AA10: 3 | AB10: 214 | AC10: 0 | AD10: 0 | AE10: 0 | AF10: 0 | AG10: 0 | AH10: 0 | AI10: 0 | AJ10: 0 | AK10: 0 | AL10: 0 | AM10: 0 | AN10: 0 | AO10: 0 | AP10: 0 | AQ10: 0 | AR10: 0 | AS10: 0 | AT10: 0 | AU10: 0 | AV10: 0 | AW10: 0 | AX10: 0 | AY10: 0 | AZ10: 0 | BA10: 0 | BB10: 0 | BC10: 0 | BD10: 0 | BE10: 0 | BF10: 0 | BG10: 0 | BH10: 0 | BI10: 0 | BJ10: 0 | BK10: 0 | BL10: 0 | BM10: 0 | BN10: 0 | BO10: 0 | BP10: 0 | BQ10: 0 | BR10: 0 | BS10: 0 | BT10: 289 | BU10: 0 | BV10: 169616 | BW10: 24472 | BX10: 0 | BY10: 194088 | BZ10: 52913 | CA10: 12201 | CB10: 65114 | CC10: 575 | CD10: 6579 | CE10: 0 | CF10: 7154 | CG10: 266356
A11: 327 | B11: Nonmetallic mineral products | C11: 0 | D11: 0 | E11: 0 | F11: 265 | G11: 0 | H11: 0 | I11: 0 | J11: 48 | K11: 168062 | L11: 134 | M11: 250 | N11: 206 | O11: 12 | P11: 88 | Q11: 0 | R11: 0 | S11: 43 | T11: 30 | U11: 0 | V11: 1 | W11: 17 | X11: 33 | Y11: 0 | Z11: 225 | AA11: 125 | AB11: 102 | AC11: 0 | AD11: 0 | AE11: 0 | AF11: 0 | AG11: 0 | AH11: 0 | AI11: 0 | AJ11: 0 | AK11: 0 | AL11: 0 | AM11: 0 | AN11: 0 | AO11: 0 | AP11: 0 | AQ11: 0 | AR11: 0 | AS11: 0 | AT11: 0 | AU11: 0 | AV11: 0 | AW11: 0 | AX11: 0 | AY11: 0 | AZ11: 0 | BA11: 0 | BB11: 0 | BC11: 0 | BD11: 0 | BE11: 0 | BF11: 0 | BG11: 0 | BH11: 0 | BI11: 0 | BJ11: 0 | BK11: 0 | BL11: 0 | BM11: 0 | BN11: 0 | BO11: 0 | BP11: 0 | BQ11: 0 | BR11: 0 | BS11: 0 | BT11: 0 | BU11: 0 | BV11: 169640 | BW11: 32384 | BX11: 0 | BY11: 202024 | BZ11: 60077 | CA11: 35416 | CB11: 95492 | CC11: 1895 | CD11: 7209 | CE11: 0 | CF11: 9104 | CG11: 306620
A12: 331 | B12: Primary metals | C12: 0 | D12: 0 | E12: 0 | F12: 0 | G12: 0 | H12: 0 | I12: 0 | J12: 0 | K12: 1 | L12: 295542 | M12: 4077 | N12: 24 | O12: 58 | P12: 1056 | Q12: 17 | R12: 2 | S12: 28 | T12: 9 | U12: 0 | V12: 0 | W12: 0 | X12: 0 | Y12: 0 | Z12: 163 | AA12: 4 | AB12: 6 | AC12: 0 | AD12: 0 | AE12: 0 | AF12: 0 | AG12: 0 | AH12: 0 | AI12: 0 | AJ12: 0 | AK12: 0 | AL12: 0 | AM12: 0 | AN12: 0 | AO12: 0 | AP12: 0 | AQ12: 0 | AR12: 0 | AS12: 0 | AT12: 0 | AU12: 0 | AV12: 0 | AW12: 0 | AX12: 0 | AY12: 0 | AZ12: 0 | BA12: 0 | BB12: 0 | BC12: 0 | BD12: 0 | BE12: 0 | BF12: 0 | BG12: 0 | BH12: 0 | BI12: 0 | BJ12: 0 | BK12: 0 | BL12: 0 | BM12: 0 | BN12: 0 | BO12: 0 | BP12: 0 | BQ12: 0 | BR12: 0 | BS12: 0 | BT12: 0 | BU12: 0 | BV12: 300987 | BW12: 95092 | BX12: 0 | BY12: 396078 | BZ12: 44963 | CA12: 15442 | CB12: 60406 | CC12: 2509 | CD12: 2742 | CE12: 0 | CF12: 5251 | CG12: 461735
A13: 332 | B13: Fabricated metal products | C13: 0 | D13: 0 | E13: 0 | F13: 0 | G13: 486 | H13: 0 | I13: 0 | J13: 646 | K13: 34 | L13: 1656 | M13: 429782 | N13: 1847 | O13: 115 | P13: 179 | Q13: 1099 | R13: 72 | S13: 243 | T13: 924 | U13: 0 | V13: 78 | W13: 0 | X13: 0 | Y13: 128 | Z13: 0 | AA13: 52 | AB13: 556 | AC13: 0 | AD13: 0 | AE13: 0 | AF13: 0 | AG13: 0 | AH13: 0 | AI13: 0 | AJ13: 0 | AK13: 0 | AL13: 0 | AM13: 0 | AN13: 0 | AO13: 0 | AP13: 0 | AQ13: 0 | AR13: 0 | AS13: 0 | AT13: 0 | AU13: 0 | AV13: 0 | AW13: 0 | AX13: 0 | AY13: 0 | AZ13: 0 | BA13: 0 | BB13: 0 | BC13: 0 | BD13: 0 | BE13: 0 | BF13: 0 | BG13: 0 | BH13: 0 | BI13: 0 | BJ13: 0 | BK13: 0 | BL13: 0 | BM13: 0 | BN13: 0 | BO13: 0 | BP13: 0 | BQ13: 0 | BR13: 0 | BS13: 0 | BT13: 0 | BU13: 0 | BV13: 437898 | BW13: 89042 | BX13: 0 | BY13: 526940 | BZ13: 176407 | CA13: 15111 | CB13: 191517 | CC13: 6053 | CD13: 20006 | CE13: 0 | CF13: 26059 | CG13: 744516
A14: 333 | B14: Machinery | C14: 0 | D14: 0 | E14: 224 | F14: 0 | G14: 0 | H14: 0 | I14: 0 | J14: 0 | K14: 8 | L14: 271 | M14: 3218 | N14: 411309 | O14: 587 | P14: 458 | Q14: 1523 | R14: 749 | S14: 55 | T14: 207 | U14: 0 | V14: 5 | W14: 0 | X14: 0 | Y14: 90 | Z14: 0 | AA14: 150 | AB14: 342 | AC14: 1 | AD14: 0 | AE14: 0 | AF14: 0 | AG14: 0 | AH14: 0 | AI14: 0 | AJ14: 0 | AK14: 0 | AL14: 0 | AM14: 0 | AN14: 0 | AO14: 0 | AP14: 0 | AQ14: 0 | AR14: 0 | AS14: 0 | AT14: 0 | AU14: 0 | AV14: 0 | AW14: 0 | AX14: 0 | AY14: 0 | AZ14: 0 | BA14: 0 | BB14: 0 | BC14: 0 | BD14: 0 | BE14: 0 | BF14: 0 | BG14: 0 | BH14: 0 | BI14: 0 | BJ14: 0 | BK14: 0 | BL14: 0 | BM14: 0 | BN14: 0 | BO14: 0 | BP14: 0 | BQ14: 4 | BR14: 0 | BS14: 0 | BT14: 0 | BU14: 0 | BV14: 419201 | BW14: 231060 | BX14: 0 | BY14: 650261 | BZ14: 261123 | CA14: 19582 | CB14: 280704 | CC14: 7225 | CD14: 20441 | CE14: 0 | CF14: 27666 | CG14: 958632
... A76: T017 | B76: Total industry supply | C76: 572741 | D76: 67211 | E76: 438824 | F76: 135721 | G76: 110289 | H76: 603774 | I76: 2508497 | J76: 173952 | K76: 175089 | L76: 301892 | M76: 458799 | N76: 436395 | O76: 411954 | P76: 193119 | Q76: 770569 | R76: 376961 | S76: 84552 | T76: 177699 | U76: 1238463 | V76: 46827 | W76: 21862 | X76: 218686 | Y76: 84346 | Z76: 649257 | AA76: 990617 | AB76: 297324 | AC76: 2629509 | AD76: 485502 | AE76: 318257 | AF76: 254347 | AG76: 1468895 | AH76: 299488 | AI76: 95998 | AJ76: 77194 | AK76: 526269 | AL76: 176504 | AM76: 73123 | AN76: 354422 | AO76: 188312 | AP76: 650245 | AQ76: 205261 | AR76: 900261 | AS76: 887224 | AT76: 1420519 | AU76: 930911 | AV76: 1496709 | AW76: 264623 | AX76: 3192628 | AY76: 2046309 | AZ76: 649989 | BA76: 461439 | BB76: 725136 | BC76: 2262334 | BD76: 855850 | BE76: 1327842 | BF76: 174691 | BG76: 494369 | BH76: 1623303 | BI76: 1256063 | BJ76: 342393 | BK76: 352390 | BL76: 312772 | BM76: 227924 | BN76: 345621 | BO76: 1279013 | BP76: 1074219 | BQ76: 891866 | BR76: 629608 | BS76: 117526 | BT76: 3297076 | BU76: 536871 | BV76: 49726230 | BW76: 3712324 | BX76: -30786 | BY76: 53407768 | BZ76: -1 | CA76: 0 | CB76: -1 | CC76: 83587 | CD76: 1016095 | CE76: -89356 | CF76: 1010326 | CG76: 54418092

Sheet Supply2024-coding
A1: IO code | B1: Commodities/Industries | C1: 111CA | D1: 113FF | E1: 211 | F1: 212 | G1: 213 | H1: 22 | I1: 23 | J1: 321 | K1: 327 | L1: 331 | M1: 332 | N1: 333 | O1: 334 | P1: 335 | Q1: 3361MV | R1: 3364OT | S1: 337 | T1: 339 | U1: 311FT | V1: 313TT | W1: 315AL | X1: 322 | Y1: 323 | Z1: 324 | AA1: 325 | AB1: 326 | AC1: 42 | AD1: 441 | AE1: 445 | AF1: 452 | AG1: 4A0 | AH1: 481 | AI1: 482 | AJ1: 483 | AK1: 484 | AL1: 485 | AM1: 486 | AN1: 487OS | AO1: 493 | AP1: 511 | AQ1: 512 | AR1: 513 | AS1: 514 | AT1: 521CI | AU1: 523 | AV1: 524 | AW1: 525 | AX1: HS | AY1: ORE | AZ1: 532RL | BA1: 5411 | BB1: 5415 | BC1: 5412OP | BD1: 55 | BE1: 561 | BF1: 562 | BG1: 61 | BH1: 621 | BI1: 622 | BJ1: 623 | BK1: 624 | BL1: 711AS | BM1: 713 | BN1: 721 | BO1: 722 | BP1: 81 | BQ1: GFGD | BR1: GFGN | BS1: GFE | BT1: GSLG | BU1: GSLE | BV1: T007 | BW1: MCIF | BX1: MADJ | BY1: T013 | BZ1: Trade | CA1: Trans | CB1: T014 | CC1: MDTY | CD1: TOP | CE1: SUB | CF1: T015 | CG1: T016
A2: 111CA | B2: Farms | C2: ='Supply 2024'!C3/'Supply 2024'!C$76 -> 0.98292247 | D2: ='Supply 2024'!D3/'Supply 2024'!D$76 -> 0.00044635551 | E2: ='Supply 2024'!E3/'Supply 2024'!E$76 -> 0 | F2: ='Supply 2024'!F3/'Supply 2024'!F$76 -> 0 | G2: ='Supply 2024'!G3/'Supply 2024'!G$76 -> 0 | H2: ='Supply 2024'!H3/'Supply 2024'!H$76 -> 0 | I2: ='Supply 2024'!I3/'Supply 2024'!I$76 -> 0 | J2: ='Supply 2024'!J3/'Supply 2024'!J$76 -> 0 | ... CG2: ='Supply 2024'!CG3/'Supply 2024'!CG$76 -> 0.016242466
A3: 113FF | B3: Forestry, fishing, and related activities | C3: ='Supply 2024'!C4/'Supply 2024'!C$76 -> 0.012310975 | D3: ='Supply 2024'!D4/'Supply 2024'!D$76 -> 0.98387169 | E3: ='Supply 2024'!E4/'Supply 2024'!E$76 -> 0 | F3: ='Supply 2024'!F4/'Supply 2024'!F$76 -> 0 | G3: ='Supply 2024'!G4/'Supply 2024'!G$76 -> 0 | H3: ='Supply 2024'!H4/'Supply 2024'!H$76 -> 0 | I3: ='Supply 2024'!I4/'Supply 2024'!I$76 -> 0 | J3: ='Supply 2024'!J4/'Supply 2024'!J$76 -> 0 | ... CG3: ='Supply 2024'!CG4/'Supply 2024'!CG$76 -> 0.0021757102
A4: 211 | B4: Oil and gas extraction | C4: ='Supply 2024'!C5/'Supply 2024'!C$76 -> 0 | D4: ='Supply 2024'!D5/'Supply 2024'!D$76 -> 0 | E4: ='Supply 2024'!E5/'Supply 2024'!E$76 -> 0.8512456 | F4: ='Supply 2024'!F5/'Supply 2024'!F$76 -> 0 | G4: ='Supply 2024'!G5/'Supply 2024'!G$76 -> 0.0032732185 | H4: ='Supply 2024'!H5/'Supply 2024'!H$76 -> 0.00021531235 | I4: ='Supply 2024'!I5/'Supply 2024'!I$76 -> 0 | J4: ='Supply 2024'!J5/'Supply 2024'!J$76 -> 0 | ... CG4: ='Supply 2024'!CG5/'Supply 2024'!CG$76 -> 0.012145942
A5: 212 | B5: Mining, except oil and gas | C5: ='Supply 2024'!C6/'Supply 2024'!C$76 -> 0 | D5: ='Supply 2024'!D6/'Supply 2024'!D$76 -> 0 | E5: ='Supply 2024'!E6/'Supply 2024'!E$76 -> 0.00012533499 | F5: ='Supply 2024'!F6/'Supply 2024'!F$76 -> 0.77267335 | G5: ='Supply 2024'!G6/'Supply 2024'!G$76 -> 0 | H5: ='Supply 2024'!H6/'Supply 2024'!H$76 -> 0 | I5: ='Supply 2024'!I6/'Supply 2024'!I$76 -> 0 | J5: ='Supply 2024'!J6/'Supply 2024'!J$76 -> 0 | ... CG5: ='Supply 2024'!CG6/'Supply 2024'!CG$76 -> 0.0029663297
A6: 213 | B6: Support activities for mining | C6: ='Supply 2024'!C7/'Supply 2024'!C$76 -> 0 | D6: ='Supply 2024'!D7/'Supply 2024'!D$76 -> 0 | E6: ='Supply 2024'!E7/'Supply 2024'!E$76 -> 0.040232531 | F6: ='Supply 2024'!F7/'Supply 2024'!F$76 -> 0.07146278 | G6: ='Supply 2024'!G7/'Supply 2024'!G$76 -> 0.92384553 | H6: ='Supply 2024'!H7/'Supply 2024'!H$76 -> 0 | I6: ='Supply 2024'!I7/'Supply 2024'!I$76 -> 0 | J6: ='Supply 2024'!J7/'Supply 2024'!J$76 -> 0 | ... CG6: ='Supply 2024'!CG7/'Supply 2024'!CG$76 -> 0.0024208309
A7: 22 | B7: Utilities | C7: ='Supply 2024'!C8/'Supply 2024'!C$76 -> 0 | D7: ='Supply 2024'!D8/'Supply 2024'!D$76 -> 0 | E7: ='Supply 2024'!E8/'Supply 2024'!E$76 -> 0 | F7: ='Supply 2024'!F8/'Supply 2024'!F$76 -> 0 | G7: ='Supply 2024'!G8/'Supply 2024'!G$76 -> 0 | H7: ='Supply 2024'!H8/'Supply 2024'!H$76 -> 0.96964261 | I7: ='Supply 2024'!I8/'Supply 2024'!I$76 -> 0 | J7: ='Supply 2024'!J8/'Supply 2024'!J$76 -> 0 | ... CG7: ='Supply 2024'!CG8/'Supply 2024'!CG$76 -> 0.015327935
A8: 23 | B8: Construction | C8: ='Supply 2024'!C9/'Supply 2024'!C$76 -> 0 | D8: ='Supply 2024'!D9/'Supply 2024'!D$76 -> 0.015681957 | E8: ='Supply 2024'!E9/'Supply 2024'!E$76 -> 0.00063806902 | F8: ='Supply 2024'!F9/'Supply 2024'!F$76 -> 0.12866837 | G8: ='Supply 2024'!G9/'Supply 2024'!G$76 -> 0.06235436 | H8: ='Supply 2024'!H9/'Supply 2024'!H$76 -> 0.0062457145 | I8: ='Supply 2024'!I9/'Supply 2024'!I$76 -> 0.99977198 | J8: ='Supply 2024'!J9/'Supply 2024'!J$76 -> 0.011871091 | ... CG8: ='Supply 2024'!CG9/'Supply 2024'!CG$76 -> 0.048781148
A9: 321 | B9: Wood products | C9: ='Supply 2024'!C10/'Supply 2024'!C$76 -> 2.0951879e-05 | D9: ='Supply 2024'!D10/'Supply 2024'!D$76 -> 0 | E9: ='Supply 2024'!E10/'Supply 2024'!E$76 -> 0 | F9: ='Supply 2024'!F10/'Supply 2024'!F$76 -> 0 | G9: ='Supply 2024'!G10/'Supply 2024'!G$76 -> 0 | H9: ='Supply 2024'!H10/'Supply 2024'!H$76 -> 0 | I9: ='Supply 2024'!I10/'Supply 2024'!I$76 -> 0 | J9: ='Supply 2024'!J10/'Supply 2024'!J$76 -> 0.96511107 | ... CG9: ='Supply 2024'!CG10/'Supply 2024'!CG$76 -> 0.0048946222
A10: 327 | B10: Nonmetallic mineral products | C10: ='Supply 2024'!C11/'Supply 2024'!C$76 -> 0 | D10: ='Supply 2024'!D11/'Supply 2024'!D$76 -> 0 | E10: ='Supply 2024'!E11/'Supply 2024'!E$76 -> 0 | F10: ='Supply 2024'!F11/'Supply 2024'!F$76 -> 0.001952535 | G10: ='Supply 2024'!G11/'Supply 2024'!G$76 -> 0 | H10: ='Supply 2024'!H11/'Supply 2024'!H$76 -> 0 | I10: ='Supply 2024'!I11/'Supply 2024'!I$76 -> 0 | J10: ='Supply 2024'!J11/'Supply 2024'!J$76 -> 0.00027593819 | ... CG10: ='Supply 2024'!CG11/'Supply 2024'!CG$76 -> 0.0056345232
A11: 331 | B11: Primary metals | C11: ='Supply 2024'!C12/'Supply 2024'!C$76 -> 0 | D11: ='Supply 2024'!D12/'Supply 2024'!D$76 -> 0 | E11: ='Supply 2024'!E12/'Supply 2024'!E$76 -> 0 | F11: ='Supply 2024'!F12/'Supply 2024'!F$76 -> 0 | G11: ='Supply 2024'!G12/'Supply 2024'!G$76 -> 0 | H11: ='Supply 2024'!H12/'Supply 2024'!H$76 -> 0 | I11: ='Supply 2024'!I12/'Supply 2024'!I$76 -> 0 | J11: ='Supply 2024'!J12/'Supply 2024'!J$76 -> 0 | ... CG11: ='Supply 2024'!CG12/'Supply 2024'!CG$76 -> 0.0084849539
A12: 332 | B12: Fabricated metal products | C12: ='Supply 2024'!C13/'Supply 2024'!C$76 -> 0 | D12: ='Supply 2024'!D13/'Supply 2024'!D$76 -> 0 | E12: ='Supply 2024'!E13/'Supply 2024'!E$76 -> 0 | F12: ='Supply 2024'!F13/'Supply 2024'!F$76 -> 0 | G12: ='Supply 2024'!G13/'Supply 2024'!G$76 -> 0.0044066045 | H12: ='Supply 2024'!H13/'Supply 2024'!H$76 -> 0 | I12: ='Supply 2024'!I13/'Supply 2024'!I$76 -> 0 | J12: ='Supply 2024'!J13/'Supply 2024'!J$76 -> 0.0037136681 | ... CG12: ='Supply 2024'!CG13/'Supply 2024'!CG$76 -> 0.013681406
A13: 333 | B13: Machinery | C13: ='Supply 2024'!C14/'Supply 2024'!C$76 -> 0 | D13: ='Supply 2024'!D14/'Supply 2024'!D$76 -> 0 | E13: ='Supply 2024'!E14/'Supply 2024'!E$76 -> 0.00051045522 | F13: ='Supply 2024'!F14/'Supply 2024'!F$76 -> 0 | G13: ='Supply 2024'!G14/'Supply 2024'!G$76 -> 0 | H13: ='Supply 2024'!H14/'Supply 2024'!H$76 -> 0 | I13: ='Supply 2024'!I14/'Supply 2024'!I$76 -> 0 | J13: ='Supply 2024'!J14/'Supply 2024'!J$76 -> 0 | ... CG13: ='Supply 2024'!CG14/'Supply 2024'!CG$76 -> 0.017616053
... A75: T017 | B75: Total industry supply | C75: ='Supply 2024'!C76/'Supply 2024'!C$76 -> 1 | D75: ='Supply 2024'!D76/'Supply 2024'!D$76 -> 1 | E75: ='Supply 2024'!E76/'Supply 2024'!E$76 -> 1 | F75: ='Supply 2024'!F76/'Supply 2024'!F$76 -> 1 | G75: ='Supply 2024'!G76/'Supply 2024'!G$76 -> 1 | H75: ='Supply 2024'!H76/'Supply 2024'!H$76 -> 1 | I75: ='Supply 2024'!I76/'Supply 2024'!I$76 -> 1 | J75: ='Supply 2024'!J76/'Supply 2024'!J$76 -> 1 | ... CG75: ='Supply 2024'!CG76/'Supply 2024'!CG$76 -> 1

Sheet Use 2024
A1: IOCode | B1: Commodities/Industries | C1: PCE share | D1: total use | E1: 111CA | F1: 113FF | G1: 211 | H1: 212 | I1: 213 | J1: 22 | K1: 23 | L1: 321 | M1: 327 | N1: 331 | O1: 332 | P1: 333 | Q1: 334 | R1: 335 | S1: 3361MV | T1: 3364OT | U1: 337 | V1: 339 | W1: 311FT | X1: 313TT | Y1: 315AL | Z1: 322 | AA1: 323 | AB1: 324 | AC1: 325 | AD1: 326 | AE1: 42 | AF1: 441 | AG1: 445 | AH1: 452 | AI1: 4A0 | AJ1: 481 | AK1: 482 | AL1: 483 | AM1: 484 | AN1: 485 | AO1: 486 | AP1: 487OS | AQ1: 493 | AR1: 511 | AS1: 512 | AT1: 513 | AU1: 514 | AV1: 521CI | AW1: 523 | AX1: 524 | AY1: 525 | AZ1: HS | BA1: ORE | BB1: 532RL | BC1: 5411 | BD1: 5415 | BE1: 5412OP | BF1: 55 | BG1: 561 | BH1: 562 | BI1: 61 | BJ1: 621 | BK1: 622 | BL1: 623 | BM1: 624 | BN1: 711AS | BO1: 713 | BP1: 721 | BQ1: 722 | BR1: 81 | BS1: GFGD | BT1: GFGN | BU1: GFE | BV1: GSLG | BW1: GSLE | BX1: T001 | BY1: F010 | BZ1: F02S | CA1: F02E | CB1: F02N | CC1: F02R | CD1: F030 | CE1: F040 | CF1: F06C | CG1: F06S | CH1: F06E | CI1: F06N | CJ1: F07C | CK1: F07S | CL1: F07E | CM1: F07N | CN1: F10C | CO1: F10S | CP1: F10E | CQ1: F10N
A2: 111CA | B2: Farms | C2: =IFERROR(BY2/D2, 0) -> 0.30392474 | D2: =BX2+BY2 -> 812971 | E2: 144746 | F2: 163 | G2: 0 | H2: 38 | I2: 18 | J2: 0 | K2: 3493 | L2: 0 | M2: 0 | N2: 0 | O2: 0 | P2: 0 | Q2: 0 | R2: 0 | S2: 0 | T2: 0 | U2: 0 | V2: 125 | W2: 377534 | X2: 1082 | Y2: 0 | Z2: 0 | AA2: 0 | AB2: 0 | AC2: 16315 | AD2: 0 | AE2: 1174 | AF2: 410 | AG2: 1121 | AH2: 242 | AI2: 206 | AJ2: 0 | AK2: 0 | AL2: 0 | AM2: 0 | AN2: 0 | AO2: 0 | AP2: 62 | AQ2: 0 | AR2: 0 | AS2: 0 | AT2: 0 | AU2: 0 | AV2: 0 | AW2: 0 | AX2: 0 | AY2: 0 | AZ2: 0 | BA2: 2 | BB2: 0 | BC2: 1 | BD2: 0 | BE2: 1174 | BF2: 45 | BG2: 1560 | BH2: 0 | BI2: 331 | BJ2: 0 | BK2: 0 | BL2: 0 | BM2: 0 | BN2: 0 | BO2: 483 | BP2: 80 | BQ2: 8441 | BR2: 14 | BS2: 69 | BT2: 110 | BU2: 0 | BV2: 6851 | BW2: 0 | BX2: 565889 | BY2: 247082 | BZ2: 0 | CA2: 0 | CB2: 0 | CC2: 0 | CD2: 281 | CE2: 70632 | CF2: 0 | CG2: 0 | CH2: 0 | CI2: 0 | CJ2: 0 | CK2: 0 | CL2: 0 | CM2: 0 | CN2: 0 | CO2: 0 | CP2: 0 | CQ2: 0
A3: 113FF | B3: Forestry, fishing, and related activities | C3: =IFERROR(BY3/D3, 0) -> 0.12448958 | D3: =BX3+BY3 -> 111182 | E3: 31647 | F3: 9457 | G3: 0 | H3: 139 | I3: 0 | J3: 0 | K3: 0 | L3: 23738 | M3: 1 | N3: 0 | O3: 0 | P3: 0 | Q3: 0 | R3: 0 | S3: 0 | T3: 0 | U3: 137 | V3: 339 | W3: 8379 | X3: 0 | Y3: 118 | Z3: 4922 | AA3: 37 | AB3: 0 | AC3: 512 | AD3: 2313 | AE3: 0 | AF3: 0 | AG3: 566 | AH3: 0 | AI3: 0 | AJ3: 0 | AK3: 0 | AL3: 0 | AM3: 0 | AN3: 0 | AO3: 0 | AP3: 2 | AQ3: 0 | AR3: 0 | AS3: 0 | AT3: 0 | AU3: 0 | AV3: 0 | AW3: 0 | AX3: 0 | AY3: 0 | AZ3: 0 | BA3: 0 | BB3: 0 | BC3: 0 | BD3: 0 | BE3: 246 | BF3: 27 | BG3: 6 | BH3: 0 | BI3: 45 | BJ3: 0 | BK3: 0 | BL3: 0 | BM3: 0 | BN3: 0 | BO3: 376 | BP3: 357 | BQ3: 7388 | BR3: 100 | BS3: 0 | BT3: 19 | BU3: 15 | BV3: 6456 | BW3: 0 | BX3: 97341 | BY3: 13841 | BZ3: 0 | CA3: 0 | CB3: 0 | CC3: 0 | CD3: 464 | CE3: 6751 | CF3: 0 | CG3: 0 | CH3: 0 | CI3: 0 | CJ3: 0 | CK3: 0 | CL3: 0 | CM3: 0 | CN3: 0 | CO3: 0 | CP3: 0 | CQ3: 0
A4: 211 | B4: Oil and gas extraction | C4: =IFERROR(BY4/D4, 0) -> 0 | D4: =BX4+BY4 -> 516161 | E4: 0 | F4: 0 | G4: 38396 | H4: 19 | I4: 71 | J4: 31670 | K4: 0 | L4: 28 | M4: 9 | N4: 14 | O4: 8 | P4: 0 | Q4: 0 | R4: 0 | S4: 1 | T4: 0 | U4: 0 | V4: 0 | W4: 25 | X4: 0 | Y4: 0 | Z4: 15 | AA4: 5 | AB4: 397943 | AC4: 14632 | AD4: 26 | AE4: 78 | AF4: 47 | AG4: 13 | AH4: 11 | AI4: 127 | AJ4: 0 | AK4: 0 | AL4: 0 | AM4: 0 | AN4: 0 | AO4: 74 | AP4: 0 | AQ4: 604 | AR4: 407 | AS4: 32 | AT4: 42 | AU4: 205 | AV4: 0 | AW4: 0 | AX4: 0 | AY4: 0 | AZ4: 0 | BA4: 187 | BB4: 0 | BC4: 0 | BD4: 7 | BE4: 106 | BF4: 19 | BG4: 24 | BH4: 88 | BI4: 1654 | BJ4: 705 | BK4: 15 | BL4: 30 | BM4: 41 | BN4: 35 | BO4: 252 | BP4: 44 | BQ4: 30 | BR4: 196 | BS4: 0 | BT4: 0 | BU4: 1172 | BV4: 0 | BW4: 27057 | BX4: 516161 | BY4: 0 | BZ4: 0 | CA4: 0 | CB4: 0 | CC4: 0 | CD4: -951 | CE4: 145749 | CF4: 0 | CG4: 0 | CH4: 0 | CI4: 0 | CJ4: 0 | CK4: 0 | CL4: 0 | CM4: 0 | CN4: 0 | CO4: 0 | CP4: 0 | CQ4: 0
A5: 212 | B5: Mining, except oil and gas | C5: =IFERROR(BY5/D5, 0) -> 0.0029328395 | D5: =BX5+BY5 -> 132295 | E5: 1984 | F5: 0 | G5: 90 | H5: 11728 | I5: 154 | J5: 7755 | K5: 34975 | L5: 11 | M5: 17329 | N5: 16593 | O5: 582 | P5: 104 | Q5: 5 | R5: 93 | S5: 92 | T5: 109 | U5: 17 | V5: 155 | W5: 1530 | X5: 33 | Y5: 0 | Z5: 1586 | AA5: 0 | AB5: 2818 | AC5: 6299 | AD5: 140 | AE5: 27 | AF5: 0 | AG5: 0 | AH5: 0 | AI5: 3 | AJ5: 0 | AK5: 127 | AL5: 0 | AM5: 8 | AN5: 0 | AO5: 0 | AP5: 1 | AQ5: 2 | AR5: 21 | AS5: 18 | AT5: 203 | AU5: 1833 | AV5: 0 | AW5: 0 | AX5: 0 | AY5: 0 | AZ5: 8 | BA5: 0 | BB5: 0 | BC5: 0 | BD5: 0 | BE5: 1800 | BF5: 41 | BG5: 1311 | BH5: 78 | BI5: 831 | BJ5: 0 | BK5: 33 | BL5: 51 | BM5: 293 | BN5: 539 | BO5: 1075 | BP5: 180 | BQ5: 1225 | BR5: 1703 | BS5: 0 | BT5: 4660 | BU5: 0 | BV5: 3221 | BW5: 8432 | BX5: 131907 | BY5: 388 | BZ5: 0 | CA5: 379 | CB5: 0 | CC5: 0 | CD5: -340 | CE5: 29088 | CF5: 0 | CG5: 0 | CH5: 0 | CI5: 0 | CJ5: 0 | CK5: 0 | CL5: 0 | CM5: 0 | CN5: 0 | CO5: 0 | CP5: 0 | CQ5: 0
A6: 213 | B6: Support activities for mining | C6: =IFERROR(BY6/D6, 0) -> 0 | D6: =BX6+BY6 -> 29371 | E6: 0 | F6: 0 | G6: 24547 | H6: 2335 | I6: 2454 | J6: 0 | K6: 0 | L6: 0 | M6: 0 | N6: 0 | O6: 0 | P6: 0 | Q6: 0 | R6: 0 | S6: 0 | T6: 0 | U6: 0 | V6: 0 | W6: 0 | X6: 0 | Y6: 0 | Z6: 0 | AA6: 0 | AB6: 0 | AC6: 0 | AD6: 0 | AE6: 0 | AF6: 0 | AG6: 0 | AH6: 0 | AI6: 0 | AJ6: 0 | AK6: 0 | AL6: 0 | AM6: 0 | AN6: 0 | AO6: 0 | AP6: 0 | AQ6: 0 | AR6: 0 | AS6: 0 | AT6: 0 | AU6: 0 | AV6: 0 | AW6: 0 | AX6: 0 | AY6: 0 | AZ6: 0 | BA6: 0 | BB6: 0 | BC6: 0 | BD6: 0 | BE6: 31 | BF6: 4 | BG6: 0 | BH6: 0 | BI6: 0 | BJ6: 0 | BK6: 0 | BL6: 0 | BM6: 0 | BN6: 0 | BO6: 0 | BP6: 0 | BQ6: 0 | BR6: 0 | BS6: 0 | BT6: 0 | BU6: 0 | BV6: 0 | BW6: 0 | BX6: 29371 | BY6: 0 | BZ6: 96938 | CA6: 3314 | CB6: 0 | CC6: 0 | CD6: -15 | CE6: 2129 | CF6: 0 | CG6: 0 | CH6: 0 | CI6: 0 | CJ6: 0 | CK6: 0 | CL6: 0 | CM6: 0 | CN6: 0 | CO6: 0 | CP6: 0 | CQ6: 0
A7: 22 | B7: Utilities | C7: =IFERROR(BY7/D7, 0) -> 0.44669652 | D7: =BX7+BY7 -> 829064 | E7: 12109 | F7: 61 | G7: 8400 | H7: 3724 | I7: 357 | J7: 33647 | K7: 14763 | L7: 2150 | M7: 5399 | N7: 6601 | O7: 5448 | P7: 2341 | Q7: 1278 | R7: 1515 | S7: 3374 | T7: 2973 | U7: 714 | V7: 784 | W7: 11575 | X7: 737 | Y7: 229 | Z7: 6628 | AA7: 1210 | AB7: 2494 | AC7: 14190 | AD7: 5389 | AE7: 15680 | AF7: 6294 | AG7: 8884 | AH7: 5778 | AI7: 17209 | AJ7: 2596 | AK7: 80 | AL7: 199 | AM7: 6664 | AN7: 842 | AO7: 2310 | AP7: 1412 | AQ7: 3100 | AR7: 1234 | AS7: 636 | AT7: 9490 | AU7: 7643 | AV7: 5129 | AW7: 2209 | AX7: 823 | AY7: 3179 | AZ7: 149 | BA7: 43660 | BB7: 2430 | BC7: 776 | BD7: 1346 | BE7: 7734 | BF7: 5089 | BG7: 4848 | BH7: 2493 | BI7: 7941 | BJ7: 6756 | BK7: 10533 | BL7: 4786 | BM7: 2016 | BN7: 1871 | BO7: 4866 | BP7: 6427 | BQ7: 28689 | BR7: 10635 | BS7: 6047 | BT7: 1253 | BU7: 2926 | BV7: 39495 | BW7: 6477 | BX7: 458724 | BY7: 370340 | BZ7: 0 | CA7: 0 | CB7: 0 | CC7: 0 | CD7: 0 | CE7: 5053 | CF7: 0 | CG7: 0 | CH7: 0 | CI7: 0 | CJ7: 0 | CK7: 0 | CL7: 0 | CM7: 0 | CN7: 0 | CO7: 0 | CP7: 0 | CQ7: 0
A8: 23 | B8: Construction | C8: =IFERROR(BY8/D8, 0) -> 0 | D8: =BX8+BY8 -> 396989 | E8: 2130 | F8: 30 | G8: 381 | H8: 3874 | I8: 1708 | J8: 4965 | K8: 620 | L8: 496 | M8: 1340 | N8: 1577 | O8: 1721 | P8: 878 | Q8: 474 | R8: 328 | S8: 917 | T8: 497 | U8: 165 | V8: 318 | W8: 2883 | X8: 106 | Y8: 4 | Z8: 1348 | AA8: 331 | AB8: 5369 | AC8: 2142 | AD8: 994 | AE8: 5562 | AF8: 2578 | AG8: 1321 | AH8: 2032 | AI8: 5189 | AJ8: 445 | AK8: 2990 | AL8: 63 | AM8: 683 | AN8: 815 | AO8: 2718 | AP8: 1070 | AQ8: 927 | AR8: 597 | AS8: 119 | AT8: 3261 | AU8: 2272 | AV8: 7530 | AW8: 2735 | AX8: 1319 | AY8: 218 | AZ8: 85174 | BA8: 58125 | BB8: 1870 | BC8: 227 | BD8: 116 | BE8: 3399 | BF8: 1104 | BG8: 1221 | BH8: 253 | BI8: 2327 | BJ8: 1158 | BK8: 3442 | BL8: 866 | BM8: 1007 | BN8: 417 | BO8: 969 | BP8: 3067 | BQ8: 4426 | BR8: 7576 | BS8: 13203 | BT8: 838 | BU8: 628 | BV8: 48481 | BW8: 77058 | BX8: 396989 | BY8: 0 | BZ8: 797005 | CA8: 0 | CB8: 0 | CC8: 965104 | CD8: 0 | CE8: 127 | CF8: 0 | CG8: 17092 | CH8: 0 | CI8: 0 | CJ8: 0 | CK8: 20235 | CL8: 0 | CM8: 0 | CN8: 0 | CO8: 458026 | CP8: 0 | CQ8: 0
A9: 321 | B9: Wood products | C9: =IFERROR(BY9/D9, 0) -> 0.038913059 | D9: =BX9+BY9 -> 239277 | E9: 1220 | F9: 70 | G9: 0 | H9: 425 | I9: 216 | J9: 9 | K9: 105452 | L9: 42622 | M9: 368 | N9: 628 | O9: 266 | P9: 988 | Q9: 517 | R9: 1056 | S9: 3979 | T9: 242 | U9: 8831 | V9: 1412 | W9: 579 | X9: 68 | Y9: 1 | Z9: 5636 | AA9: 2 | AB9: 0 | AC9: 337 | AD9: 2583 | AE9: 11733 | AF9: 366 | AG9: 1034 | AH9: 211 | AI9: 2172 | AJ9: 0 | AK9: 4992 | AL9: 0 | AM9: 357 | AN9: 0 | AO9: 6 | AP9: 93 | AQ9: 138 | AR9: 56 | AS9: 91 | AT9: 870 | AU9: 2059 | AV9: 219 | AW9: 9 | AX9: 0 | AY9: 0 | AZ9: 41 | BA9: 10183 | BB9: 1153 | BC9: 14 | BD9: 38 | BE9: 1145 | BF9: 7 | BG9: 1395 | BH9: 46 | BI9: 85 | BJ9: 780 | BK9: 785 | BL9: 7 | BM9: 1070 | BN9: 14 | BO9: 382 | BP9: 1499 | BQ9: 1810 | BR9: 661 | BS9: 59 | BT9: 112 | BU9: 2 | BV9: 6187 | BW9: 579 | BX9: 229966 | BY9: 9311 | BZ9: 608 | CA9: 0 | CB9: 0 | CC9: 18762 | CD9: 1460 | CE9: 6228 | CF9: 0 | CG9: 0 | CH9: 0 | CI9: 0 | CJ9: 0 | CK9: 0 | CL9: 19 | CM9: 0 | CN9: 0 | CO9: 0 | CP9: 0 | CQ9: 0
A10: 327 | B10: Nonmetallic mineral products | C10: =IFERROR(BY10/D10, 0) -> 0.10096296 | D10: =BX10+BY10 -> 293365 | E10: 26 | F10: 109 | G10: 2289 | H10: 743 | I10: 984 | J10: 42 | K10: 155061 | L10: 1295 | M10: 27523 | N10: 4072 | O10: 2045 | P10: 1769 | Q10: 313 | R10: 2343 | S10: 9081 | T10: 360 | U10: 381 | V10: 951 | W10: 5001 | X10: 46 | Y10: 0 | Z10: 540 | AA10: 1 | AB10: 1299 | AC10: 2064 | AD10: 2647 | AE10: 132 | AF10: 396 | AG10: 53 | AH10: 466 | AI10: 1020 | AJ10: 0 | AK10: 20 | AL10: 0 | AM10: 180 | AN10: 0 | AO10: 0 | AP10: 16 | AQ10: 71 | AR10: 3 | AS10: 2 | AT10: 2340 | AU10: 1005 | AV10: 35 | AW10: 60 | AX10: 80 | AY10: 0 | AZ10: 147 | BA10: 68 | BB10: 1474 | BC10: 0 | BD10: 262 | BE10: 6960 | BF10: 36 | BG10: 1280 | BH10: 376 | BI10: 135 | BJ10: 4064 | BK10: 4078 | BL10: 218 | BM10: 905 | BN10: 16 | BO10: 238 | BP10: 128 | BQ10: 3953 | BR10: 2671 | BS10: 162 | BT10: 990 | BU10: 0 | BV10: 3038 | BW10: 5684 | BX10: 263746 | BY10: 29619 | BZ10: 0 | CA10: 0 | CB10: 0 | CC10: 0 | CD10: 1227 | CE10: 12028 | CF10: 0 | CG10: 0 | CH10: 0 | CI10: 0 | CJ10: 0 | CK10: 0 | CL10: 0 | CM10: 0 | CN10: 0 | CO10: 0 | CP10: 0 | CQ10: 0
A11: 331 | B11: Primary metals | C11: =IFERROR(BY11/D11, 0) -> 0.0093469231 | D11: =BX11+BY11 -> 422278 | E11: 99 | F11: 0 | G11: 10134 | H11: 771 | I11: 286 | J11: 4 | K11: 10333 | L11: 369 | M11: 2828 | N11: 97471 | O11: 113570 | P11: 44259 | Q11: 4191 | R11: 30765 | S11: 60399 | T11: 7615 | U11: 4552 | V11: 5814 | W11: 2571 | X11: 138 | Y11: 0 | Z11: 1566 | AA11: 25 | AB11: 14 | AC11: 38 | AD11: 2278 | AE11: 749 | AF11: 9 | AG11: 0 | AH11: 0 | AI11: 723 | AJ11: 0 | AK11: 813 | AL11: 0 | AM11: 0 | AN11: 0 | AO11: 0 | AP11: 124 | AQ11: 0 | AR11: 14 | AS11: 9 | AT11: 397 | AU11: 1397 | AV11: 0 | AW11: 0 | AX11: 0 | AY11: 0 | AZ11: 2 | BA11: 3955 | BB11: 194 | BC11: 0 | BD11: 0 | BE11: 1987 | BF11: 45 | BG11: 904 | BH11: 362 | BI11: 409 | BJ11: 252 | BK11: 47 | BL11: 23 | BM11: 460 | BN11: 38 | BO11: 594 | BP11: 43 | BQ11: 275 | BR11: 1005 | BS11: 707 | BT11: 1363 | BU11: 0 | BV11: 164 | BW11: 1174 | BX11: 418331 | BY11: 3947 | BZ11: 0 | CA11: 0 | CB11: 0 | CC11: 0 | CD11: -502 | CE11: 39960 | CF11: 0 | CG11: 0 | CH11: 0 | CI11: 0 | CJ11: 0 | CK11: 0 | CL11: 0 | CM11: 0 | CN11: 0 | CO11: 0 | CP11: 0 | CQ11: 0
A12: 332 | B12: Fabricated metal products | C12: =IFERROR(BY12/D12, 0) -> 0.14844529 | D12: =BX12+BY12 -> 668583 | E12: 1995 | F12: 217 | G12: 14854 | H12: 1339 | I12: 758 | J12: 1293 | K12: 194169 | L12: 4740 | M12: 3221 | N12: 7005 | O12: 52490 | P12: 27516 | Q12: 7912 | R12: 18392 | S12: 32491 | T12: 15350 | U12: 5993 | V12: 4609 | W12: 22978 | X12: 509 | Y12: 62 | Z12: 6535 | AA12: 1049 | AB12: 569 | AC12: 9646 | AD12: 9692 | AE12: 4484 | AF12: 645 | AG12: 365 | AH12: 231 | AI12: 3069 | AJ12: 339 | AK12: 401 | AL12: 1804 | AM12: 2221 | AN12: 816 | AO12: 2334 | AP12: 470 | AQ12: 1094 | AR12: 881 | AS12: 48 | AT12: 11513 | AU12: 3739 | AV12: 459 | AW12: 369 | AX12: 0 | AY12: 37 | AZ12: 38 | BA12: 1975 | BB12: 3762 | BC12: 33 | BD12: 3697 | BE12: 8837 | BF12: 679 | BG12: 4255 | BH12: 4791 | BI12: 635 | BJ12: 638 | BK12: 2865 | BL12: 48 | BM12: 4390 | BN12: 94 | BO12: 1122 | BP12: 2720 | BQ12: 6062 | BR12: 7823 | BS12: 13122 | BT12: 2207 | BU12: 216 | BV12: 6848 | BW12: 11776 | BX12: 569335 | BY12: 99248 | BZ12: 0 | CA12: 19742 | CB12: 0 | CC12: 0 | CD12: 2641 | CE12: 53268 | CF12: 0 | CG12: 0 | CH12: 93 | CI12: 0 | CJ12: 0 | CK12: 0 | CL12: 76 | CM12: 0 | CN12: 0 | CO12: 0 | CP12: 113 | CQ12: 0
A13: 333 | B13: Machinery | C13: =IFERROR(BY13/D13, 0) -> 0.13890233 | D13: =BX13+BY13 -> 361549 | E13: 4018 | F13: 37 | G13: 16801 | H13: 5816 | I13: 4335 | J13: 933 | K13: 73186 | L13: 801 | M13: 244 | N13: 2278 | O13: 6981 | P13: 43504 | Q13: 401 | R13: 3428 | S13: 44654 | T13: 3938 | U13: 207 | V13: 657 | W13: 7957 | X13: 39 | Y13: 2 | Z13: 1243 | AA13: 1815 | AB13: 72 | AC13: 7115 | AD13: 3943 | AE13: 3234 | AF13: 385 | AG13: 161 | AH13: 107 | AI13: 967 | AJ13: 22 | AK13: 77 | AL13: 54 | AM13: 638 | AN13: 96 | AO13: 85 | AP13: 4004 | AQ13: 1769 | AR13: 80 | AS13: 32 | AT13: 1314 | AU13: 1961 | AV13: 7 | AW13: 54 | AX13: 483 | AY13: 0 | AZ13: 89 | BA13: 332 | BB13: 2220 | BC13: 21 | BD13: 3153 | BE13: 4101 | BF13: 525 | BG13: 7828 | BH13: 6349 | BI13: 2881 | BJ13: 1892 | BK13: 1181 | BL13: 219 | BM13: 344 | BN13: 31 | BO13: 452 | BP13: 105 | BQ13: 1288 | BR13: 10730 | BS13: 3303 | BT13: 777 | BU13: 44 | BV13: 8710 | BW13: 4822 | BX13: 311329 | BY13: 50220 | BZ13: 0 | CA13: 433823 | CB13: 0 | CC13: 0 | CD13: 1499 | CE13: 146544 | CF13: 0 | CG13: 0 | CH13: 2504 | CI13: 0 | CJ13: 0 | CK13: 0 | CL13: 67 | CM13: 0 | CN13: 0 | CO13: 0 | CP13: 12648 | CQ13: 0
... A84: VAPRO | B84: Value Added (producer prices) | C84: =IFERROR(BY84/D84, 0) -> 0 | D84: =BX84+BY84 -> 29298013 | E84: 215830 | F84: 53856 | G84: 252608 | H84: 80799 | I84: 70840 | J84: 454357 | K84: 1305402 | L84: 60171 | M84: 77516 | N84: 76516 | O84: 190535 | P84: 208621 | Q84: 299783 | R84: 80171 | S84: 185854 | T84: 197330 | U84: 34448 | V84: 113897 | W84: 360176 | X84: 16316 | Y84: 12453 | Z84: 74433 | AA84: 41301 | AB84: 195712 | AC84: 554021 | AD84: 101471 | AE84: 1706289 | AF84: 356851 | AG84: 236132 | AH84: 224084 | AI84: 1031973 | AJ84: 175712 | AK84: 53169 | AL84: 24335 | AM84: 257356 | AN84: 83850 | AO84: 48501 | AP84: 216231 | AQ84: 128148 | AR84: 442706 | AS84: 119385 | AT84: 501545 | AU84: 529056 | AV84: 1013285 | AW84: 396082 | AX84: 791806 | AY84: 27981 | AZ84: 2853988 | BA84: 830242 | BB84: 368169 | BC84: 387719 | BD84: 522249 | BE84: 1445101 | BF84: 544333 | BG84: 823102 | BH84: 88601 | BI84: 334785 | BJ84: 1078954 | BK84: 691481 | BL84: 212314 | BM84: 226633 | BN84: 190761 | BO84: 136004 | BP84: 257248 | BQ84: 703108 | BR84: 627985 | BS84: 549405 | BT84: 437372 | BU84: 78079 | BV84: 2073333 | BW84: 158152 | BX84: 29298013 | BY84: 0 | BZ84: 0 | CA84: 0 | CB84: 0 | CC84: 0 | CD84: 0 | CE84: 0 | CF84: 0 | CG84: 0 | CH84: 0 | CI84: 0 | CJ84: 0 | CK84: 0 | CL84: 0 | CM84: 0 | CN84: 0 | CO84: 0 | CP84: 0 | CQ84: 0

Sheet B2C
A1: IO code | B1: Commodities/Industries | C1: 111CA | D1: 113FF | E1: 211 | F1: 212 | G1: 213 | H1: 22 | I1: 23 | J1: 321 | K1: 327 | L1: 331 | M1: 332 | N1: 333 | O1: 334 | P1: 335 | Q1: 3361MV | R1: 3364OT | S1: 337 | T1: 339 | U1: 311FT | V1: 313TT | W1: 315AL | X1: 322 | Y1: 323 | Z1: 324 | AA1: 325 | AB1: 326 | AC1: 42 | AD1: 441 | AE1: 445 | AF1: 452 | AG1: 4A0 | AH1: 481 | AI1: 482 | AJ1: 483 | AK1: 484 | AL1: 485 | AM1: 486 | AN1: 487OS | AO1: 493 | AP1: 511 | AQ1: 512 | AR1: 513 | AS1: 514 | AT1: 521CI | AU1: 523 | AV1: 524 | AW1: 525 | AX1: HS | AY1: ORE | AZ1: 532RL | BA1: 5411 | BB1: 5415 | BC1: 5412OP | BD1: 55 | BE1: 561 | BF1: 562 | BG1: 61 | BH1: 621 | BI1: 622 | BJ1: 623 | BK1: 624 | BL1: 711AS | BM1: 713 | BN1: 721 | BO1: 722 | BP1: 81 | BQ1: GFGD | BR1: GFGN | BS1: GFE | BT1: GSLG | BU1: GSLE | BV1: T007 | BW1: MCIF | BX1: MADJ | BY1: T013 | BZ1: Trade | CA1: Trans | CB1: T014 | CC1: MDTY | CD1: TOP | CE1: SUB | CF1: T015 | CG1: T016
C2: Farms | D2: Forestry, fishing, and related activities | E2: Oil and gas extraction | F2: Mining, except oil and gas | G2: Support activities for mining | H2: Utilities | I2: Construction | J2: Wood products | K2: Nonmetallic mineral products | L2: Primary metals | M2: Fabricated metal products | N2: Machinery | O2: Computer and electronic products | P2: Electrical equipment, appliances, and components | Q2: Motor vehicles, bodies and trailers, and parts | R2: Other transportation equipment | S2: Furniture and related products | T2: Miscellaneous manufacturing | U2: Food and beverage and tobacco products | V2: Textile mills and textile product mills | W2: Apparel and leather and allied products | X2: Paper products | Y2: Printing and related support activities | Z2: Petroleum and coal products | AA2: Chemical products | AB2: Plastics and rubber products | AC2: Wholesale trade | AD2: Motor vehicle and parts dealers | AE2: Food and beverage stores | AF2: General merchandise stores | AG2: Other retail | AH2: Air transportation | AI2: Rail transportation | AJ2: Water transportation | AK2: Truck transportation | AL2: Transit and ground passenger transportation | AM2: Pipeline transportation | AN2: Other transportation and support activities | AO2: Warehousing and storage | AP2: Publishing industries, except internet (includes software) | AQ2: Motion picture and sound recording industries | AR2: Broadcasting and telecommunications | AS2: Data processing, internet publishing, and other information services | AT2: Federal Reserve banks, credit intermediation, and related activities | AU2: Securities, commodity contracts, and investments | AV2: Insurance carriers and related activities | AW2: Funds, trusts, and other financial vehicles | AX2: Housing | AY2: Other real estate | AZ2: Rental and leasing services and lessors of intangible assets | BA2: Legal services | BB2: Computer systems design and related services | BC2: Miscellaneous professional, scientific, and technical services | BD2: Management of companies and enterprises | BE2: Administrative and support services | BF2: Waste management and remediation services | BG2: Educational services | BH2: Ambulatory health care services | BI2: Hospitals | BJ2: Nursing and residential care facilities | BK2: Social assistance | BL2: Performing arts, spectator sports, museums, and related activities | BM2: Amusements, gambling, and recreation industries | BN2: Accommodation | BO2: Food services and drinking places | BP2: Other services, except government | BQ2: Federal general government (defense) | BR2: Federal general government (nondefense) | BS2: Federal government enterprises | BT2: State and local general government | BU2: State and local government enterprises | BV2: Total Commodity Output | BW2: Imports | BX2: CIF/FOB Adjustments on Imports | BY2: Total product supply (basic prices) | BZ2: Trade margins | CA2: Transport margins | CB2: Total trade and transportation margins | CC2: Import duties | CD2: Tax on products | CE2: Subsidies | CF2: Total tax less subsidies on products | CG2: Total product supply (purchaser prices)
A3: 111CA | B3: Farms | C3: ='Supply2024-coding'!C2*'Use 2024'!$C2 -> 0.29873446 | D3: ='Supply2024-coding'!D2*'Use 2024'!$C2 -> 0.00013565848 | E3: ='Supply2024-coding'!E2*'Use 2024'!$C2 -> 0 | F3: ='Supply2024-coding'!F2*'Use 2024'!$C2 -> 0 | G3: ='Supply2024-coding'!G2*'Use 2024'!$C2 -> 0 | H3: ='Supply2024-coding'!H2*'Use 2024'!$C2 -> 0 | I3: ='Supply2024-coding'!I2*'Use 2024'!$C2 -> 0 | J3: ='Supply2024-coding'!J2*'Use 2024'!$C2 -> 0 | ... CG3: ='Supply2024-coding'!CG2*'Use 2024'!$C2 -> 0.0049364872
A4: 113FF | B4: Forestry, fishing, and related activities | C4: ='Supply2024-coding'!C3*'Use 2024'!$C3 -> 0.001532588 | D4: ='Supply2024-coding'!D3*'Use 2024'!$C3 -> 0.12248177 | E4: ='Supply2024-coding'!E3*'Use 2024'!$C3 -> 0 | F4: ='Supply2024-coding'!F3*'Use 2024'!$C3 -> 0 | G4: ='Supply2024-coding'!G3*'Use 2024'!$C3 -> 0 | H4: ='Supply2024-coding'!H3*'Use 2024'!$C3 -> 0 | I4: ='Supply2024-coding'!I3*'Use 2024'!$C3 -> 0 | J4: ='Supply2024-coding'!J3*'Use 2024'!$C3 -> 0 | ... CG4: ='Supply2024-coding'!CG3*'Use 2024'!$C3 -> 0.00027085324
A5: 211 | B5: Oil and gas extraction | C5: ='Supply2024-coding'!C4*'Use 2024'!$C4 -> 0 | D5: ='Supply2024-coding'!D4*'Use 2024'!$C4 -> 0 | E5: ='Supply2024-coding'!E4*'Use 2024'!$C4 -> 0 | F5: ='Supply2024-coding'!F4*'Use 2024'!$C4 -> 0 | G5: ='Supply2024-coding'!G4*'Use 2024'!$C4 -> 0 | H5: ='Supply2024-coding'!H4*'Use 2024'!$C4 -> 0 | I5: ='Supply2024-coding'!I4*'Use 2024'!$C4 -> 0 | J5: ='Supply2024-coding'!J4*'Use 2024'!$C4 -> 0 | ... CG5: ='Supply2024-coding'!CG4*'Use 2024'!$C4 -> 0
A6: 212 | B6: Mining, except oil and gas | C6: ='Supply2024-coding'!C5*'Use 2024'!$C5 -> 0 | D6: ='Supply2024-coding'!D5*'Use 2024'!$C5 -> 0 | E6: ='Supply2024-coding'!E5*'Use 2024'!$C5 -> 3.675874e-07 | F6: ='Supply2024-coding'!F5*'Use 2024'!$C5 -> 0.0022661269 | G6: ='Supply2024-coding'!G5*'Use 2024'!$C5 -> 0 | H6: ='Supply2024-coding'!H5*'Use 2024'!$C5 -> 0 | I6: ='Supply2024-coding'!I5*'Use 2024'!$C5 -> 0 | J6: ='Supply2024-coding'!J5*'Use 2024'!$C5 -> 0 | ... CG6: ='Supply2024-coding'!CG5*'Use 2024'!$C5 -> 8.6997687e-06
A7: 213 | B7: Support activities for mining | C7: ='Supply2024-coding'!C6*'Use 2024'!$C6 -> 0 | D7: ='Supply2024-coding'!D6*'Use 2024'!$C6 -> 0 | E7: ='Supply2024-coding'!E6*'Use 2024'!$C6 -> 0 | F7: ='Supply2024-coding'!F6*'Use 2024'!$C6 -> 0 | G7: ='Supply2024-coding'!G6*'Use 2024'!$C6 -> 0 | H7: ='Supply2024-coding'!H6*'Use 2024'!$C6 -> 0 | I7: ='Supply2024-coding'!I6*'Use 2024'!$C6 -> 0 | J7: ='Supply2024-coding'!J6*'Use 2024'!$C6 -> 0 | ... CG7: ='Supply2024-coding'!CG6*'Use 2024'!$C6 -> 0
A8: 22 | B8: Utilities | C8: ='Supply2024-coding'!C7*'Use 2024'!$C7 -> 0 | D8: ='Supply2024-coding'!D7*'Use 2024'!$C7 -> 0 | E8: ='Supply2024-coding'!E7*'Use 2024'!$C7 -> 0 | F8: ='Supply2024-coding'!F7*'Use 2024'!$C7 -> 0 | G8: ='Supply2024-coding'!G7*'Use 2024'!$C7 -> 0 | H8: ='Supply2024-coding'!H7*'Use 2024'!$C7 -> 0.43313598 | I8: ='Supply2024-coding'!I7*'Use 2024'!$C7 -> 0 | J8: ='Supply2024-coding'!J7*'Use 2024'!$C7 -> 0 | ... CG8: ='Supply2024-coding'!CG7*'Use 2024'!$C7 -> 0.0068469353
A9: 23 | B9: Construction | C9: ='Supply2024-coding'!C8*'Use 2024'!$C8 -> 0 | D9: ='Supply2024-coding'!D8*'Use 2024'!$C8 -> 0 | E9: ='Supply2024-coding'!E8*'Use 2024'!$C8 -> 0 | F9: ='Supply2024-coding'!F8*'Use 2024'!$C8 -> 0 | G9: ='Supply2024-coding'!G8*'Use 2024'!$C8 -> 0 | H9: ='Supply2024-coding'!H8*'Use 2024'!$C8 -> 0 | I9: ='Supply2024-coding'!I8*'Use 2024'!$C8 -> 0 | J9: ='Supply2024-coding'!J8*'Use 2024'!$C8 -> 0 | ... CG9: ='Supply2024-coding'!CG8*'Use 2024'!$C8 -> 0
A10: 321 | B10: Wood products | C10: ='Supply2024-coding'!C9*'Use 2024'!$C9 -> 8.1530169e-07 | D10: ='Supply2024-coding'!D9*'Use 2024'!$C9 -> 0 | E10: ='Supply2024-coding'!E9*'Use 2024'!$C9 -> 0 | F10: ='Supply2024-coding'!F9*'Use 2024'!$C9 -> 0 | G10: ='Supply2024-coding'!G9*'Use 2024'!$C9 -> 0 | H10: ='Supply2024-coding'!H9*'Use 2024'!$C9 -> 0 | I10: ='Supply2024-coding'!I9*'Use 2024'!$C9 -> 0 | J10: ='Supply2024-coding'!J9*'Use 2024'!$C9 -> 0.037555424 | ... CG10: ='Supply2024-coding'!CG9*'Use 2024'!$C9 -> 0.00019046472
A11: 327 | B11: Nonmetallic mineral products | C11: ='Supply2024-coding'!C10*'Use 2024'!$C10 -> 0 | D11: ='Supply2024-coding'!D10*'Use 2024'!$C10 -> 0 | E11: ='Supply2024-coding'!E10*'Use 2024'!$C10 -> 0 | F11: ='Supply2024-coding'!F10*'Use 2024'!$C10 -> 0.00019713372 | G11: ='Supply2024-coding'!G10*'Use 2024'!$C10 -> 0 | H11: ='Supply2024-coding'!H10*'Use 2024'!$C10 -> 0 | I11: ='Supply2024-coding'!I10*'Use 2024'!$C10 -> 0 | J11: ='Supply2024-coding'!J10*'Use 2024'!$C10 -> 2.7859538e-05 | ... CG11: ='Supply2024-coding'!CG10*'Use 2024'!$C10 -> 0.00056887816
A12: 331 | B12: Primary metals | C12: ='Supply2024-coding'!C11*'Use 2024'!$C11 -> 0 | D12: ='Supply2024-coding'!D11*'Use 2024'!$C11 -> 0 | E12: ='Supply2024-coding'!E11*'Use 2024'!$C11 -> 0 | F12: ='Supply2024-coding'!F11*'Use 2024'!$C11 -> 0 | G12: ='Supply2024-coding'!G11*'Use 2024'!$C11 -> 0 | H12: ='Supply2024-coding'!H11*'Use 2024'!$C11 -> 0 | I12: ='Supply2024-coding'!I11*'Use 2024'!$C11 -> 0 | J12: ='Supply2024-coding'!J11*'Use 2024'!$C11 -> 0 | ... CG12: ='Supply2024-coding'!CG11*'Use 2024'!$C11 -> 7.9308211e-05
A13: 332 | B13: Fabricated metal products | C13: ='Supply2024-coding'!C12*'Use 2024'!$C12 -> 0 | D13: ='Supply2024-coding'!D12*'Use 2024'!$C12 -> 0 | E13: ='Supply2024-coding'!E12*'Use 2024'!$C12 -> 0 | F13: ='Supply2024-coding'!F12*'Use 2024'!$C12 -> 0 | G13: ='Supply2024-coding'!G12*'Use 2024'!$C12 -> 0.0006541397 | H13: ='Supply2024-coding'!H12*'Use 2024'!$C12 -> 0 | I13: ='Supply2024-coding'!I12*'Use 2024'!$C12 -> 0 | J13: ='Supply2024-coding'!J12*'Use 2024'!$C12 -> 0.00055127656 | ... CG13: ='Supply2024-coding'!CG12*'Use 2024'!$C12 -> 0.0020309403
A14: 333 | B14: Machinery | C14: ='Supply2024-coding'!C13*'Use 2024'!$C13 -> 0 | D14: ='Supply2024-coding'!D13*'Use 2024'!$C13 -> 0 | E14: ='Supply2024-coding'!E13*'Use 2024'!$C13 -> 7.0903421e-05 | F14: ='Supply2024-coding'!F13*'Use 2024'!$C13 -> 0 | G14: ='Supply2024-coding'!G13*'Use 2024'!$C13 -> 0 | H14: ='Supply2024-coding'!H13*'Use 2024'!$C13 -> 0 | I14: ='Supply2024-coding'!I13*'Use 2024'!$C13 -> 0 | J14: ='Supply2024-coding'!J13*'Use 2024'!$C13 -> 0 | ... CG14: ='Supply2024-coding'!CG13*'Use 2024'!$C13 -> 0.0024469109
... A75: Other | B75: Noncomparable imports and rest-of-the-world adjustment | C75: ='Supply2024-coding'!C74*'Use 2024'!$C74 -> 0 | D75: ='Supply2024-coding'!D74*'Use 2024'!$C74 -> 0 | E75: ='Supply2024-coding'!E74*'Use 2024'!$C74 -> 0 | F75: ='Supply2024-coding'!F74*'Use 2024'!$C74 -> 0 | G75: ='Supply2024-coding'!G74*'Use 2024'!$C74 -> 0 | H75: ='Supply2024-coding'!H74*'Use 2024'!$C74 -> 0 | I75: ='Supply2024-coding'!I74*'Use 2024'!$C74 -> 0 | J75: ='Supply2024-coding'!J74*'Use 2024'!$C74 -> 0 | ... CG75: ='Supply2024-coding'!CG74*'Use 2024'!$C74 -> -0.0018304428
A76: T017 | B76: Total industry supply | C76: =SUM(C3:C75) -> 0.30445731 | D76: =SUM(D3:D75) -> 0.12261743 | E76: =SUM(E3:E75) -> 0.049423769 | F76: =SUM(F3:F75) -> 0.013914118 | G76: =SUM(G3:G75) -> 0.0017762434 | H76: =SUM(H3:H75) -> 0.44188793 | I76: =SUM(I3:I75) -> 9.0323186e-07 | J76: =SUM(J3:J75) -> 0.044058822 | ... CG76: =SUM(CG3:CG75) -> 0.39586994
A83: IO code | B83: Commodities/Industries | C83: 111CA | D83: 113FF | E83: 211 | F83: 212 | G83: 213 | H83: 22 | I83: 23 | J83: 321 | K83: 327 | L83: 331 | M83: 332 | N83: 333 | O83: 334 | P83: 335 | Q83: 3361MV | R83: 3364OT | S83: 337 | T83: 339 | U83: 311FT | V83: 313TT | W83: 315AL | X83: 322 | Y83: 323 | Z83: 324 | AA83: 325 | AB83: 326 | AC83: 42 | AD83: 441 | AE83: 445 | AF83: 452 | AG83: 4A0 | AH83: 481 | AI83: 482 | AJ83: 483 | AK83: 484 | AL83: 485 | AM83: 486 | AN83: 487OS | AO83: 493 | AP83: 511 | AQ83: 512 | AR83: 513 | AS83: 514 | AT83: 521CI | AU83: 523 | AV83: 524 | AW83: 525 | AX83: HS | AY83: ORE | AZ83: 532RL | BA83: 5411 | BB83: 5415 | BC83: 5412OP | BD83: 55 | BE83: 561 | BF83: 562 | BG83: 61 | BH83: 621 | BI83: 622 | BJ83: 623 | BK83: 624 | BL83: 711AS | BM83: 713 | BN83: 721 | BO83: 722 | BP83: 81 | BQ83: GFGD | BR83: GFGN | BS83: GFE | BT83: GSLG | BU83: GSLE | BV83: T007 | BW83: MCIF | BX83: MADJ | BY83: T013 | BZ83: Trade | CA83: Trans | CB83: T014 | CC83: MDTY | CD83: TOP | CE83: SUB | CF83: T015 | CG83: T016
C84: Farms | D84: Forestry, fishing, and related activities | E84: Oil and gas extraction | F84: Mining, except oil and gas | G84: Support activities for mining | H84: Utilities | I84: Construction | J84: Wood products | K84: Nonmetallic mineral products | L84: Primary metals | M84: Fabricated metal products | N84: Machinery | O84: Computer and electronic products | P84: Electrical equipment, appliances, and components | Q84: Motor vehicles, bodies and trailers, and parts | R84: Other transportation equipment | S84: Furniture and related products | T84: Miscellaneous manufacturing | U84: Food and beverage and tobacco products | V84: Textile mills and textile product mills | W84: Apparel and leather and allied products | X84: Paper products | Y84: Printing and related support activities | Z84: Petroleum and coal products | AA84: Chemical products | AB84: Plastics and rubber products | AC84: Wholesale trade | AD84: Motor vehicle and parts dealers | AE84: Food and beverage stores | AF84: General merchandise stores | AG84: Other retail | AH84: Air transportation | AI84: Rail transportation | AJ84: Water transportation | AK84: Truck transportation | AL84: Transit and ground passenger transportation | AM84: Pipeline transportation | AN84: Other transportation and support activities | AO84: Warehousing and storage | AP84: Publishing industries, except internet (includes software) | AQ84: Motion picture and sound recording industries | AR84: Broadcasting and telecommunications | AS84: Data processing, internet publishing, and other information services | AT84: Federal Reserve banks, credit intermediation, and related activities | AU84: Securities, commodity contracts, and investments | AV84: Insurance carriers and related activities | AW84: Funds, trusts, and other financial vehicles | AX84: Housing | AY84: Other real estate | AZ84: Rental and leasing services and lessors of intangible assets | BA84: Legal services | BB84: Computer systems design and related services | BC84: Miscellaneous professional, scientific, and technical services | BD84: Management of companies and enterprises | BE84: Administrative and support services | BF84: Waste management and remediation services | BG84: Educational services | BH84: Ambulatory health care services | BI84: Hospitals | BJ84: Nursing and residential care facilities | BK84: Social assistance | BL84: Performing arts, spectator sports, museums, and related activities | BM84: Amusements, gambling, and recreation industries | BN84: Accommodation | BO84: Food services and drinking places | BP84: Other services, except government | BQ84: Federal general government (defense) | BR84: Federal general government (nondefense) | BS84: Federal government enterprises | BT84: State and local general government | BU84: State and local government enterprises | BV84: Total Commodity Output | BW84: Imports | BX84: CIF/FOB Adjustments on Imports | BY84: Total product supply (basic prices) | BZ84: Trade margins | CA84: Transport margins | CB84: Total trade and transportation margins | CC84: Import duties | CD84: Tax on products | CE84: Subsidies | CF84: Total tax less subsidies on products | CG84: Total product supply (purchaser prices)
A85: T017 | B85: Total industry supply | C85: =SUM(C11:C83) -> 0.30864677 | D85: =SUM(D11:D83) -> 0.12261743 | E85: =SUM(E11:E83) -> 0.09884717 | F85: =SUM(F11:F83) -> 0.02556211 | G85: =SUM(G11:G83) -> 0.0035524869 | H85: =SUM(H11:H83) -> 0.45063989 | I85: =SUM(I11:I83) -> 1.8064637e-06 | J85: =SUM(J11:J83) -> 0.050562221 | ... CG85: =SUM(CG11:CG83) -> 0.77948643
A88: 111CA | B88: Farms | C88: 0.30864677
A89: 113FF | B89: Forestry, fishing, and related activities | C89: 0.12261743
A90: 211 | B90: Oil and gas extraction | C90: 0.09884717
A91: 212 | B91: Mining, except oil and gas | C91: 0.02556211
A92: 213 | B92: Support activities for mining | C92: 0.0035524869
A93: 22 | B93: Utilities | C93: 0.45063989
A94: 23 | B94: Construction | C94: 1.8064637e-06
A95: 321 | B95: Wood products | C95: 0.050562221
A96: 327 | B96: Nonmetallic mineral products | C96: 0.20018522
A97: 331 | B97: Primary metals | C97: 0.027400004
A98: 332 | B98: Fabricated metal products | C98: 0.30034344
A99: 333 | B99: Machinery | C99: 0.27397568
... A163: Trade | B163: Trade margins | C163: -2271269.3
A164: Trans | B164: Transport margins | C164: #DIV/0!
A165: T014 | B165: Total trade and transportation margins | C165: -2427236.2
A166: MDTY | B166: Import duties | C166: 1.0296352
A167: TOP | B167: Tax on products | C167: 1.0143576
A168: SUB | B168: Subsidies | C168: 1.5639702
A169: T015 | B169: Total tax less subsidies on products | C169: 0.96701115
A170: T016 | B170: Total product supply (purchaser prices) | C170: 0.77948643

Sheet personal consumption
A1: IOCode | B1: Name | C1: B2C | H1: Descriptive stats of personal expendisuture output
A2: 111CA | B2: Farms | C2: 0.30864677 | G2: Count | H2: Mean | I2: sd | J2: p25 | K2: median | L2: p75
A3: 113FF | B3: Forestry, fishing, and related activities | C3: 0.12261743 | G3: =COUNT(#REF!) -> 0 | H3: =AVERAGE(#REF!) -> #REF! | I3: =_xlfn.STDEV.S(#REF!) -> #REF! | J3: =_xlfn.PERCENTILE.INC(#REF!, 0.25) -> #REF! | K3: =MEDIAN(#REF!) -> #REF! | L3: =_xlfn.PERCENTILE.INC(#REF!, 0.75) -> #REF!
A4: 211 | B4: Oil and gas extraction | C4: 0.09884717
A5: 212 | B5: Mining, except oil and gas | C5: 0.02556211
A6: 213 | B6: Support activities for mining | C6: 0.0035524869
A7: 22 | B7: Utilities | C7: 0.45063989
A8: 23 | B8: Construction | C8: 1.8064637e-06
A9: 321 | B9: Wood products | C9: 0.050562221
A10: 327 | B10: Nonmetallic mineral products | C10: 0.20018522
A11: 331 | B11: Primary metals | C11: 0.027400004
A12: 332 | B12: Fabricated metal products | C12: 0.30034344
A13: 333 | B13: Machinery | C13: 0.27397568
A14: 334 | B14: Computer and electronic products | C14: 0.59473046
A15: 335 | B15: Electrical equipment, appliances, and components | C15: 0.79353177
... A77: Trade | B77: Trade margins | C77: -2271269.3
A78: Trans | B78: Transport margins | C78: #DIV/0!
A79: T014 | B79: Total trade and transportation margins | C79: -2427236.2
A80: MDTY | B80: Import duties | C80: 1.0296352
A81: TOP | B81: Tax on products | C81: 1.0143576
A82: SUB | B82: Subsidies | C82: 1.5639702
A83: T015 | B83: Total tax less subsidies on products | C83: 0.96701115
A84: T016 | B84: Total product supply (purchaser prices) | C84: 0.77948643

Sheet SASB Industries
A1: Main Industry | B1: SASB Industry | C1: ind_code | D1: Corresponding IO Industry | E1: B2C
A2: Consumer Goods | B2: APPAREL, ACCESSORIES & FOOTWEAR | C2: CG-AA | D2: Apparel and leather and allied products | E2: =_xlfn.XLOOKUP(D2, 'personal consumption'!$B$2:$B$83,'personal consumption'!$C$2:$C$83) -> 1.8850639
A3: Consumer Goods | B3: APPLIANCE MANUFACTURING | C3: CG-AM | D3: Electrical equipment, appliances, and components | E3: =_xlfn.XLOOKUP(D3, 'personal consumption'!$B$2:$B$83,'personal consumption'!$C$2:$C$83) -> 0.79353177
A4: Consumer Goods | B4: BUILDING PRODUCTS & FURNISHINGS | C4: CG-BF | D4: Miscellaneous manufacturing | E4: =_xlfn.XLOOKUP(D4, 'personal consumption'!$B$2:$B$83,'personal consumption'!$C$2:$C$83) -> 1.2913113
A5: Consumer Goods | B5: E-COMMERCE | C5: CG-EC | D5: Miscellaneous manufacturing | E5: =_xlfn.XLOOKUP(D5, 'personal consumption'!$B$2:$B$83,'personal consumption'!$C$2:$C$83) -> 1.2913113
A6: Consumer Goods | B6: HOUSEHOLD & PERSONAL PRODUCTS | C6: CG-HP | D6: Housing | E6: =_xlfn.XLOOKUP(D6, 'personal consumption'!$B$2:$B$83,'personal consumption'!$C$2:$C$83) -> 1.9812882
A7: Consumer Goods | B7: MULTILINE AND SPECIALTY RETAILERS & DISTRIBUTORS | C7: CG-MR | D7: Miscellaneous manufacturing | E7: =_xlfn.XLOOKUP(D7, 'personal consumption'!$B$2:$B$83,'personal consumption'!$C$2:$C$83) -> 1.2913113
A8: Consumer Goods | B8: TOYS & SPORTING GOODS | C8: CG-TS | D8: Miscellaneous manufacturing | E8: =_xlfn.XLOOKUP(D8, 'personal consumption'!$B$2:$B$83,'personal consumption'!$C$2:$C$83) -> 1.2913113
A9: Extractives & Minerals | B9: CONSTRUCTION MATERIALS | C9: EM-CM | D9: Nonmetallic mineral products | E9: =_xlfn.XLOOKUP(D9, 'personal consumption'!$B$2:$B$83,'personal consumption'!$C$2:$C$83) -> 0.20018522
A10: Extractives & Minerals | B10: COAL OPERATIONS | C10: EM-CO | D10: Mining, except oil and gas | E10: =_xlfn.XLOOKUP(D10, 'personal consumption'!$B$2:$B$83,'personal consumption'!$C$2:$C$83) -> 0.02556211
A11: Extractives & Minerals | B11: OIL & GAS - EXPLORATION & PRODUCTION | C11: EM-EP | D11: Oil and gas extraction | E11: =_xlfn.XLOOKUP(D11, 'personal consumption'!$B$2:$B$83,'personal consumption'!$C$2:$C$83) -> 0.09884717
A12: Extractives & Minerals | B12: IRON & STEEL PRODUCERS | C12: EM-IS | D12: Mining, except oil and gas | E12: =_xlfn.XLOOKUP(D12, 'personal consumption'!$B$2:$B$83,'personal consumption'!$C$2:$C$83) -> 0.02556211
A13: Extractives & Minerals | B13: OIL & GAS - MIDSTREAM | C13: EM-MD | D13: Oil and gas extraction | E13: =_xlfn.XLOOKUP(D13, 'personal consumption'!$B$2:$B$83,'personal consumption'!$C$2:$C$83) -> 0.09884717
